Workbook
Name a: [1]销售明细!$P$7:$P$5003

Sheet 主页 
O2: 今天是： | R2: =TODAY() -> 46151 | T2: =TEXT(WEEKDAY(R2,1),"aaaa") -> 星期六
P19: 当月采购数量： | S19: =SUMIFS('采购录入（明细）'!I:I,'采购录入（明细）'!L:L,YEAR(TODAY()),'采购录入（明细）'!M:M,MONTH(TODAY())) -> 0
P20: 当月领取数量： | S20: =SUMIFS('领用录入（明细）'!I:I,'领用录入（明细）'!M:M,YEAR(TODAY()),'领用录入（明细）'!N:N,MONTH(TODAY())) -> 0

Sheet 基础-办公用品信息
B2: ="办公用品信息-设定（"&COUNTA(C4:C34)&"类用品）" -> 办公用品信息-设定（31类用品）
B3: NO: | C3: 办公用品名称 | D3: 单位 | E3: 型号 | F3: 单价 | G3: 备注
B4: 1 | C4: A3打印纸 | D4: 包 | F4: 175
B5: 2 | C5: A4打印纸 | D5: 包 | F5: 175
B6: 3 | C6: A4装订封面纸 | D6: 包 | F6: 18
B7: 4 | C7: A4复印纸蓝色 | D7: 包
B8: 5 | C8: A4复印纸红色 | D8: 包
B9: 6 | C9: A4白卡纸180克荷兰白卡 | D9: 包
B10: 7 | C10: 定制会议本牛皮A4 | D10: 本
B11: 8 | C11: 定制会议本活页B5 | D11: 本
B12: 9 | C12: 定制会议便签本牛皮书写夹板A4 | D12: 本
B13: 10 | C13: 会议记录本皮面黑色 | D13: 本 | F13: 7.5
B14: 11 | C14: office本32k | D14: 本
B15: 12 | C15: 软面抄100 | D15: 本 | F15: 1.5
B16: 13 | C16: 透明暗扣袋 | D16: 个
B17: 14 | C17: 挂快牢得力A4 | D17: 张
B18: 15 | C18: 资料册40页 | D18: 本 | F18: 6.5
B19: 16 | C19: 档案袋牛皮纸（小） | D19: 只
B20: 17 | C20: 档案盒牛皮纸 | D20: 只
B21: 18 | C21: 档案盒大塑料 | D21: 只
B22: 19 | C22: 档案盒小塑料 | D22: 只
B23: 20 | C23: 三角抽杆文件夹 | D23: 本 | F23: 0.55
B24: 21 | C24: 塑料文件架 | D24: 只 | F24: 18
B25: 22 | C25: 文件夹，纸板夹 | D25: 本 | F25: 5
B26: 23 | C26: 文件夹，塑料皮 | D26: 本 | F26: 6.5
B27: 24 | C27: 网格拉链袋 | D27: 只
B28: 25 | C28: 书写夹板A5 | D28: 只
B29: 26 | C29: 铁书挡（小） | D29: 只
B30: 27 | C30: 铁书挡（大） | D30: 只
B31: 28 | C31: 水笔黑色 | D31: 支 | F31: 1.3
B32: 29 | C32: 水笔红色 | D32: 支 | F32: 1.3
B33: 30 | C33: 按压水笔黑色 | D33: 支 | F33: 2
B34: 31 | C34: 笔芯 | D34: 支
B35: 32 | C35: 台笔 | D35: 支
B36: 33 | C36: 记号笔黑色 | D36: 支 | F36: 0.5
B37: 34 | C37: 记号笔红色 | D37: 支 | F37: 0.5
B38: 35 | C38: 扑克 | D38: 盒 | F38: 1.4
B39: 36 | C39: 圆珠笔蓝色 | D39: 支
B40: 37 | C40: 铅笔 | D40: 支 | F40: 7元/盒
B41: 38 | C41: 卷笔机 | D41: 个 | F41: 16
...

Sheet 基础-领用人及部门
B2: 领用人信息-设置
B3: NO: | C3: 姓名 | D3: 所属部门 | E3: 备注
B4: 1 | C4: 杨红艳 | D4: 综合办
B5: 2 | C5: 余慧娟 | D5: 综合办 | G5: 部门信息-设置
B6: 3 | C6: 蔡迎亚 | D6: 综合办 | G6: NO: | H6: 部门 | I6: 备注
B7: 4 | C7: 文丽梅 | D7: 综合办 | G7: 1 | H7: 综合办
B8: 5 | C8: 杨 迁 | D8: 综合办 | G8: 2 | H8: 财务部
B9: 6 | C9: 杨 雪 | D9: 综合办 | G9: 3 | H9: 开发部
B10: 7 | C10: 刘海山 | D10: 综合办 | G10: 4 | H10: 招采部
B11: 8 | C11: 蔡宏斌 | D11: 综合办 | G11: 5 | H11: 技术部
B12: 9 | C12: 吴小转 | D12: 综合办 | G12: 6 | H12: 成本部
B13: 10 | C13: 范小红 | D13: 综合办 | G13: 7 | H13: 销售部
B14: 11 | C14: 郦 静 | D14: 综合办 | G14: 8 | H14: 工程部
B15: 12 | C15: 陈 奔 | D15: 综合办 | G15: 9 | H15: 中盛广场物业
B16: 13 | C16: 许轩铭 | D16: 综合办 | G16: 10 | H16: boss
B17: 14 | C17: 陶怡然 | D17: 综合办 | G17: 11 | H17: 四楼会议室
B18: 15 | C18: 陈圣明 | D18: 综合办 | G18: 12 | H18: 看门
B19: 16 | C19: 马丽萍 | D19: 综合办 | G19: 13
B20: 17 | C20: 王 瑾 | D20: 财务部 | G20: 14
B21: 18 | C21: 蒋 黎 | D21: 财务部 | G21: 15
B22: 19 | C22: 毛秀玲 | D22: 财务部 | G22: 16
B23: 20 | C23: 王志明 | D23: 财务部 | G23: 17
B24: 21 | C24: 王 彪 | D24: 财务部 | G24: 18
B25: 22 | C25: 王晓奇 | D25: 财务部 | G25: 19
B26: 23 | C26: 於文琪 | D26: 财务部 | G26: 20
B27: 24 | C27: 卢 萍 | D27: 财务部 | G27: 21
B28: 25 | C28: 陈楚楚 | D28: 财务部 | G28: 22
B29: 26 | C29: 陈灵星 | D29: 财务部 | G29: 23
B30: 27 | C30: 沈金辉 | D30: 开发部 | G30: 24
... B36: 33 | C36: 周芝鹏 | D36: 技术部 | G36: 30
B37: 34 | C37: 谢哲金 | D37: 技术部
B38: 35 | C38: 刘 强 | D38: 技术部
B39: 36 | C39: 陈 军 | D39: 技术部
B40: 37 | C40: 潘迦轩 | D40: 技术部
B41: 38 | C41: 何小敏 | D41: 技术部
B42: 39 | C42: 何如宋 | D42: 成本部
B43: 40 | C43: 郑 辉 | D43: 成本部
B44: 41 | C44: 金 锋 | D44: 成本部
B45: 42 | C45: 王美萍 | D45: 成本部
B46: 43 | C46: 金也莉 | D46: 成本部
...

Sheet 采购录入（明细）
B2: 采购录入（明细） | O2: 采购数量 | P2: 采购金额
B3: NO: | C3: 日期 | D3: 采购人 | E3: 办公用品名称 | F3: 单位 | G3: 型号 | H3: 单价 | I3: 数量 | J3: 金额 | K3: 备注 | L3: 辅助年 | M3: 辅助月 | O3: =SUM(I:I) -> 3307.3 | P3: =SUM(J:J) -> 31752.9
B4: 1 | C4: 44862 | D4: 陈圣明 | E4: 卷纸 | F4: =IFERROR(VLOOKUP($E4,'基础-办公用品信息'!$C:$E,2,FALSE),"-") -> 提 | G4: =IFERROR(VLOOKUP($E4,'基础-办公用品信息'!$C:$E,3,FALSE),"-") -> 0 | H4: =IFERROR(VLOOKUP($E4,'基础-办公用品信息'!$C:$F,4,FALSE),"-") -> 11.5 | I4: 12 | J4: =IF(AND(H4<>"",I4<>""),H4*I4,"-") -> 138 | L4: =YEAR(C4) -> 2022 | M4: =MONTH(C4) -> 10
B5: 2 | C5: 44862 | D5: 陈圣明 | E5: 抽纸盒 | F5: =IFERROR(VLOOKUP($E5,'基础-办公用品信息'!$C:$E,2,FALSE),"-") -> 盒 | G5: =IFERROR(VLOOKUP($E5,'基础-办公用品信息'!$C:$E,3,FALSE),"-") -> 0 | H5: =IFERROR(VLOOKUP($E5,'基础-办公用品信息'!$C:$F,4,FALSE),"-") -> 5.3 | I5: 72 | J5: =IF(AND(H5<>"",I5<>""),H5*I5,"-") -> 381.6 | L5: =YEAR(C5) -> 2022 | M5: =MONTH(C5) -> 10
B6: 3 | C6: 44866 | D6: 杨 雪 | E6: 洗洁精 | F6: 瓶 | H6: 22 | I6: 5 | J6: =IF(AND(H6<>"",I6<>""),H6*I6,"-") -> 110 | L6: =YEAR(C6) -> 2022 | M6: =MONTH(C6) -> 11
B7: 4 | C7: 44866 | D7: 杨 雪 | E7: 垃圾袋 | F7: 卷 | H7: 1.9 | I7: 10 | J7: =IF(AND(H7<>"",I7<>""),H7*I7,"-") -> 19 | L7: =YEAR(C7) -> 2022 | M7: =MONTH(C7) -> 11
B8: 5 | C8: 44866 | D8: 杨 雪 | E8: 消毒液L3 | F8: 箱 | H8: 15 | I8: 15 | J8: =IF(AND(H8<>"",I8<>""),H8*I8,"-") -> 225 | L8: =YEAR(C8) -> 2022 | M8: =MONTH(C8) -> 11
B9: 6 | C9: 44866 | D9: 杨 雪 | E9: 喷洒消毒液 | F9: 瓶 | H9: 9 | I9: 9 | J9: =IF(AND(H9<>"",I9<>""),H9*I9,"-") -> 81 | L9: =YEAR(C9) -> 2022 | M9: =MONTH(C9) -> 11
B10: 7 | C10: 44866 | D10: 杨 雪 | E10: 白手套 | F10: 打 | H10: 9 | I10: 9 | J10: =IF(AND(H10<>"",I10<>""),H10*I10,"-") -> 81 | L10: =YEAR(C10) -> 2022 | M10: =MONTH(C10) -> 11
B11: 8 | C11: 44866 | D11: 杨 雪 | E11: 马桶刷 | F11: 个 | H11: 8 | I11: 2 | J11: =IF(AND(H11<>"",I11<>""),H11*I11,"-") -> 16 | L11: =YEAR(C11) -> 2022 | M11: =MONTH(C11) -> 11
B12: 9 | C12: 44866 | D12: 杨 雪 | E12: 500消毒液 | F12: 瓶 | H12: 2.5 | I12: 2 | J12: =IF(AND(H12<>"",I12<>""),H12*I12,"-") -> 5 | L12: =YEAR(C12) -> 2022 | M12: =MONTH(C12) -> 11
B13: 10 | C13: 44881 | D13: 陶怡然 | E13: 入库单两联 | F13: 本 | H13: 0.6 | I13: 100 | J13: =IF(AND(H13<>"",I13<>""),H13*I13,"-") -> 60 | L13: =YEAR(C13) -> 2022 | M13: =MONTH(C13) -> 11
B14: 11 | C14: 44881 | D14: 陶怡然 | E14: 卷笔机 | F14: 个 | H14: 20 | I14: 5 | J14: =IF(AND(H14<>"",I14<>""),H14*I14,"-") -> 100 | L14: =YEAR(C14) -> 2022 | M14: =MONTH(C14) -> 11
B15: 12 | C15: 44881 | D15: 陶怡然 | E15: 透明直尺40cm | F15: 把 | H15: 2 | I15: 10 | J15: =IF(AND(H15<>"",I15<>""),H15*I15,"-") -> 20 | L15: =YEAR(C15) -> 2022 | M15: =MONTH(C15) -> 11
B16: 13 | C16: 44881 | D16: 陶怡然 | E16: 电池南孚27A | F16: 粒 | H16: 2.6 | I16: 50 | J16: =IF(AND(H16<>"",I16<>""),H16*I16,"-") -> 130 | L16: =YEAR(C16) -> 2022 | M16: =MONTH(C16) -> 11
B17: 14 | C17: 44881 | D17: 陶怡然 | E17: 电池南孚5号 | F17: 粒 | H17: 2.2 | I17: 60 | J17: =IF(AND(H17<>"",I17<>""),H17*I17,"-") -> 132 | L17: =YEAR(C17) -> 2022 | M17: =MONTH(C17) -> 11
... B37: 34 | C37: 44881 | D37: 陶怡然 | E37: 蓝色口罩 | F37: 包 | H37: 1.999 | I37: 100 | J37: =IF(AND(H37<>"",I37<>""),H37*I37,"-") -> 199.9 | L37: =YEAR(C37) -> 2022 | M37: =MONTH(C37) -> 11
B38: 35 | C38: 44886 | D38: 杨 雪 | E38: 安全帽 | F38: 顶 | I38: 50 | J38: =IF(AND(H38<>"",I38<>""),H38*I38,"-") -> - | L38: =YEAR(C38) -> 2022 | M38: =MONTH(C38) -> 11
B39: 36 | C39: 44889 | D39: 陶怡然 | E39: 卷纸 | F39: 提 | H39: 37.5 | I39: 40 | J39: =IF(AND(H39<>"",I39<>""),H39*I39,"-") -> 1500 | L39: =YEAR(C39) -> 2022 | M39: =MONTH(C39) -> 11
B40: 37 | C40: 44893 | D40: 余慧娟 | E40: 交换机 | F40: =IFERROR(VLOOKUP($E40,'基础-办公用品信息'!$C:$E,2,FALSE),"-") -> 个 | H40: 65 | I40: 1 | J40: =IF(AND(H40<>"",I40<>""),H40*I40,"-") -> 65 | L40: =YEAR(C40) -> 2022 | M40: =MONTH(C40) -> 11
B41: 38 | C41: 44893 | D41: 杨 迁 | E41: 尘推杆 | F41: =IFERROR(VLOOKUP($E41,'基础-办公用品信息'!$C:$E,2,FALSE),"-") -> 根 | H41: 8 | I41: 10 | J41: =IF(AND(H41<>"",I41<>""),H41*I41,"-") -> 80 | L41: =YEAR(C41) -> 2022 | M41: =MONTH(C41) -> 11
B42: 39 | C42: 44894 | D42: 杨 迁 | E42: 狗粮 | F42: =IFERROR(VLOOKUP($E42,'基础-办公用品信息'!$C:$E,2,FALSE),"-") -> 包 | H42: 170 | I42: 1 | J42: =IF(AND(H42<>"",I42<>""),H42*I42,"-") -> 170 | L42: =YEAR(C42) -> 2022 | M42: =MONTH(C42) -> 11
B43: 40 | C43: 44902 | D43: 杨 迁 | E43: 垃圾袋大 | F43: =IFERROR(VLOOKUP($E43,'基础-办公用品信息'!$C:$E,2,FALSE),"-") -> 卷 | I43: 100 | J43: =IF(AND(H43<>"",I43<>""),H43*I43,"-") -> - | L43: =YEAR(C43) -> 2022 | M43: =MONTH(C43) -> 12
B44: 41 | C44: 44902 | D44: 杨 迁 | E44: 垃圾袋小 | F44: =IFERROR(VLOOKUP($E44,'基础-办公用品信息'!$C:$E,2,FALSE),"-") -> 卷 | I44: 100 | J44: =IF(AND(H44<>"",I44<>""),H44*I44,"-") -> - | L44: =YEAR(C44) -> 2022 | M44: =MONTH(C44) -> 12
B45: 42 | C45: 44902 | D45: 杨 迁 | E45: 橡胶手套 | F45: =IFERROR(VLOOKUP($E45,'基础-办公用品信息'!$C:$E,2,FALSE),"-") -> 双 | G45: =IFERROR(VLOOKUP($E45,'基础-办公用品信息'!$C:$E,3,FALSE),"-") -> 0 | H45: 14 | I45: 3 | J45: =IF(AND(H45<>"",I45<>""),H45*I45,"-") -> 42 | L45: =YEAR(C45) -> 2022 | M45: =MONTH(C45) -> 12
B46: 43 | C46: 44909 | D46: 余慧娟 | E46: 地毯胶 | F46: =IFERROR(VLOOKUP($E46,'基础-办公用品信息'!$C:$E,2,FALSE),"-") -> 个 | G46: =IFERROR(VLOOKUP($E46,'基础-办公用品信息'!$C:$E,3,FALSE),"-") -> 0 | H46: 5 | I46: 3 | J46: =IF(AND(H46<>"",I46<>""),H46*I46,"-") -> 15 | L46: =YEAR(C46) -> 2022 | M46: =MONTH(C46) -> 12
B47: 44 | C47: 44910 | D47: 陶怡然 | E47: 插座3m | F47: =IFERROR(VLOOKUP($E47,'基础-办公用品信息'!$C:$E,2,FALSE),"-") -> 个 | G47: =IFERROR(VLOOKUP($E47,'基础-办公用品信息'!$C:$E,3,FALSE),"-") -> 0 | H47: =IFERROR(VLOOKUP($E47,'基础-办公用品信息'!$C:$F,4,FALSE),"-") -> 59 | I47: 2 | J47: =IF(AND(H47<>"",I47<>""),H47*I47,"-") -> 118 | L47: =YEAR(C47) -> 2022 | M47: =MONTH(C47) -> 12
B48: 45 | C48: 44911 | D48: 陶怡然 | E48: 电池双鹿7号 | F48: =IFERROR(VLOOKUP($E48,'基础-办公用品信息'!$C:$E,2,FALSE),"-") -> 节 | G48: =IFERROR(VLOOKUP($E48,'基础-办公用品信息'!$C:$E,3,FALSE),"-") -> 0 | H48: =IFERROR(VLOOKUP($E48,'基础-办公用品信息'!$C:$F,4,FALSE),"-") -> 0 | I48: 120 | J48: =IF(AND(H48<>"",I48<>""),H48*I48,"-") -> 0 | L48: =YEAR(C48) -> 2022 | M48: =MONTH(C48) -> 12
B49: 46 | C49: 44924 | D49: 杨 迁 | E49: 酒精消毒水 | F49: =IFERROR(VLOOKUP($E49,'基础-办公用品信息'!$C:$E,2,FALSE),"-") -> 瓶 | G49: =IFERROR(VLOOKUP($E49,'基础-办公用品信息'!$C:$E,3,FALSE),"-") -> 0 | H49: =IFERROR(VLOOKUP($E49,'基础-办公用品信息'!$C:$F,4,FALSE),"-") -> 0 | I49: 10 | J49: =IF(AND(H49<>"",I49<>""),H49*I49,"-") -> 0 | L49: =YEAR(C49) -> 2022 | M49: =MONTH(C49) -> 12
B50: 47 | C50: 44924 | D50: 杨 迁 | E50: 次氯酸消毒液 | F50: =IFERROR(VLOOKUP($E50,'基础-办公用品信息'!$C:$E,2,FALSE),"-") -> 瓶 | G50: =IFERROR(VLOOKUP($E50,'基础-办公用品信息'!$C:$E,3,FALSE),"-") -> 0 | H50: =IFERROR(VLOOKUP($E50,'基础-办公用品信息'!$C:$F,4,FALSE),"-") -> 0 | I50: 12 | J50: =IF(AND(H50<>"",I50<>""),H50*I50,"-") -> 0 | L50: =YEAR(C50) -> 2022 | M50: =MONTH(C50) -> 12
B51: 48 | C51: 44928 | D51: 杨 迁 | E51: 喷壶 | F51: =IFERROR(VLOOKUP($E51,'基础-办公用品信息'!$C:$E,2,FALSE),"-") -> 个 | G51: =IFERROR(VLOOKUP($E51,'基础-办公用品信息'!$C:$E,3,FALSE),"-") -> 0 | H51: =IFERROR(VLOOKUP($E51,'基础-办公用品信息'!$C:$F,4,FALSE),"-") -> 0 | I51: 3 | J51: =IF(AND(H51<>"",I51<>""),H51*I51,"-") -> 0 | L51: =YEAR(C51) -> 2023 | M51: =MONTH(C51) -> 1
B52: 49 | C52: 44928 | E52: A3打印纸 | F52: =IFERROR(VLOOKUP($E52,'基础-办公用品信息'!$C:$E,2,FALSE),"-") -> 包 | G52: =IFERROR(VLOOKUP($E52,'基础-办公用品信息'!$C:$E,3,FALSE),"-") -> 0 | H52: =IFERROR(VLOOKUP($E52,'基础-办公用品信息'!$C:$F,4,FALSE),"-") -> 175 | I52: 1 | J52: =IF(AND(H52<>"",I52<>""),H52*I52,"-") -> 175 | L52: =YEAR(C52) -> 2023 | M52: =MONTH(C52) -> 1
B53: 50 | C53: 44932 | D53: 余慧娟 | E53: 马桶刷 | F53: =IFERROR(VLOOKUP($E53,'基础-办公用品信息'!$C:$E,2,FALSE),"-") -> 个 | G53: =IFERROR(VLOOKUP($E53,'基础-办公用品信息'!$C:$E,3,FALSE),"-") -> 0 | H53: =IFERROR(VLOOKUP($E53,'基础-办公用品信息'!$C:$F,4,FALSE),"-") -> 0 | I53: 5 | J53: =IF(AND(H53<>"",I53<>""),H53*I53,"-") -> 0 | L53: =YEAR(C53) -> 2023 | M53: =MONTH(C53) -> 1
B54: 51 | C54: 44935 | D54: 陶怡然 | E54: 有线鼠标 | F54: =IFERROR(VLOOKUP($E54,'基础-办公用品信息'!$C:$E,2,FALSE),"-") -> 个 | G54: =IFERROR(VLOOKUP($E54,'基础-办公用品信息'!$C:$E,3,FALSE),"-") -> 0 | H54: =IFERROR(VLOOKUP($E54,'基础-办公用品信息'!$C:$F,4,FALSE),"-") -> 30 | I54: 5 | J54: =IF(AND(H54<>"",I54<>""),H54*I54,"-") -> 150 | L54: =YEAR(C54) -> 2023 | M54: =MONTH(C54) -> 1
B55: 52 | C55: 44935 | D55: 陶怡然 | E55: 无线鼠标 | F55: =IFERROR(VLOOKUP($E55,'基础-办公用品信息'!$C:$E,2,FALSE),"-") -> 个 | G55: =IFERROR(VLOOKUP($E55,'基础-办公用品信息'!$C:$E,3,FALSE),"-") -> 0 | H55: =IFERROR(VLOOKUP($E55,'基础-办公用品信息'!$C:$F,4,FALSE),"-") -> 75 | I55: 5 | J55: =IF(AND(H55<>"",I55<>""),H55*I55,"-") -> 375 | L55: =YEAR(C55) -> 2023 | M55: =MONTH(C55) -> 1
B56: 53 | C56: 44935 | D56: 陶怡然 | E56: 键盘 | F56: =IFERROR(VLOOKUP($E56,'基础-办公用品信息'!$C:$E,2,FALSE),"-") -> 个 | G56: =IFERROR(VLOOKUP($E56,'基础-办公用品信息'!$C:$E,3,FALSE),"-") -> 0 | H56: =IFERROR(VLOOKUP($E56,'基础-办公用品信息'!$C:$F,4,FALSE),"-") -> 0 | I56: 3 | J56: =IF(AND(H56<>"",I56<>""),H56*I56,"-") -> 0 | L56: =YEAR(C56) -> 2023 | M56: =MONTH(C56) -> 1
B57: 54 | C57: 44935 | D57: 陶怡然 | E57: 无线网卡 | F57: =IFERROR(VLOOKUP($E57,'基础-办公用品信息'!$C:$E,2,FALSE),"-") -> 个 | G57: =IFERROR(VLOOKUP($E57,'基础-办公用品信息'!$C:$E,3,FALSE),"-") -> 0 | H57: =IFERROR(VLOOKUP($E57,'基础-办公用品信息'!$C:$F,4,FALSE),"-") -> 0 | I57: 3 | J57: =IF(AND(H57<>"",I57<>""),H57*I57,"-") -> 0 | L57: =YEAR(C57) -> 2023 | M57: =MONTH(C57) -> 1
B58: 55 | C58: 44942 | D58: 杨 迁 | E58: 橡胶手套 | F58: =IFERROR(VLOOKUP($E58,'基础-办公用品信息'!$C:$E,2,FALSE),"-") -> 双 | G58: =IFERROR(VLOOKUP($E58,'基础-办公用品信息'!$C:$E,3,FALSE),"-") -> 0 | H58: =IFERROR(VLOOKUP($E58,'基础-办公用品信息'!$C:$F,4,FALSE),"-") -> 0 | I58: 3 | J58: =IF(AND(H58<>"",I58<>""),H58*I58,"-") -> 0 | L58: =YEAR(C58) -> 2023 | M58: =MONTH(C58) -> 1
B59: 56 | C59: 44942 | D59: 杨 迁 | E59: 院子灯泡 | F59: =IFERROR(VLOOKUP($E59,'基础-办公用品信息'!$C:$E,2,FALSE),"-") -> 个 | G59: =IFERROR(VLOOKUP($E59,'基础-办公用品信息'!$C:$E,3,FALSE),"-") -> 0 | H59: =IFERROR(VLOOKUP($E59,'基础-办公用品信息'!$C:$F,4,FALSE),"-") -> 15 | I59: 2 | J59: =IF(AND(H59<>"",I59<>""),H59*I59,"-") -> 30 | L59: =YEAR(C59) -> 2023 | M59: =MONTH(C59) -> 1
B60: 57 | C60: 44943 | D60: 余慧娟 | E60: 橡胶手套 | F60: =IFERROR(VLOOKUP($E60,'基础-办公用品信息'!$C:$E,2,FALSE),"-") -> 双 | G60: =IFERROR(VLOOKUP($E60,'基础-办公用品信息'!$C:$E,3,FALSE),"-") -> 0 | H60: =IFERROR(VLOOKUP($E60,'基础-办公用品信息'!$C:$F,4,FALSE),"-") -> 0 | I60: 5 | J60: =IF(AND(H60<>"",I60<>""),H60*I60,"-") -> 0 | L60: =YEAR(C60) -> 2023 | M60: =MONTH(C60) -> 1
...

Sheet 领用录入（明细）
B2: 领用录入（明细） | P2: 领用数量 | Q2: 领用金额
B3: NO: | C3: 日期 | D3: 领用人 | E3: 所属部门 | F3: 办公用品名称 | G3: 单位 | H3: 型号 | I3: 数量 | J3: 单价 | K3: 金额 | L3: 备注 | M3: 辅助年 | N3: 辅助月 | P3: =SUM(I4:I4998) -> 2182.3 | Q3: =SUM(K4:K4998) -> 27625.27
B4: 1 | C4: 44845 | D4: 潘迦轩 | E4: =IFERROR(VLOOKUP(D4,'基础-领用人及部门'!$C:$D,2,FALSE),"-") -> 技术部 | F4: 会议记录本皮面黑色 | G4: =IFERROR(VLOOKUP($F4,'基础-办公用品信息'!$C:$E,2,FALSE),"-") -> 本 | H4: =IFERROR(VLOOKUP($F4,'基础-办公用品信息'!$C:$E,3,FALSE),"-") -> 0 | I4: 1 | J4: =IFERROR(VLOOKUP($F4,'基础-办公用品信息'!$C:$F,4,FALSE),"-") -> 7.5 | K4: =IFERROR(I4*J4,"") -> 7.5 | M4: =YEAR(C4) -> 2022 | N4: =MONTH(C4) -> 10
B5: 2 | C5: 44845 | D5: 陈圣明 | E5: =IFERROR(VLOOKUP(D5,'基础-领用人及部门'!$C:$D,2,FALSE),"-") -> 综合办 | F5: 电池南孚27A | G5: =IFERROR(VLOOKUP($F5,'基础-办公用品信息'!$C:$E,2,FALSE),"-") -> 节 | H5: =IFERROR(VLOOKUP($F5,'基础-办公用品信息'!$C:$E,3,FALSE),"-") -> 0 | I5: 1 | J5: =IFERROR(VLOOKUP($F5,'基础-办公用品信息'!$C:$F,4,FALSE),"-") -> 0 | K5: =IFERROR(I5*J5,"") -> 0 | M5: =YEAR(C5) -> 2022 | N5: =MONTH(C5) -> 10
B6: 3 | C6: 44847 | D6: 潘迦轩 | E6: =IFERROR(VLOOKUP(D6,'基础-领用人及部门'!$C:$D,2,FALSE),"-") -> 技术部 | F6: 光盘壳 | G6: =IFERROR(VLOOKUP($F6,'基础-办公用品信息'!$C:$E,2,FALSE),"-") -> 个 | H6: =IFERROR(VLOOKUP($F6,'基础-办公用品信息'!$C:$E,3,FALSE),"-") -> 0 | I6: 12 | J6: =IFERROR(VLOOKUP($F6,'基础-办公用品信息'!$C:$F,4,FALSE),"-") -> 0 | K6: =IFERROR(I6*J6,"") -> 0 | M6: =YEAR(C6) -> 2022 | N6: =MONTH(C6) -> 10
B7: 4 | C7: 44847 | D7: 蔡宏斌 | E7: =IFERROR(VLOOKUP(D7,'基础-领用人及部门'!$C:$D,2,FALSE),"-") -> 综合办 | F7: 网格拉链袋 | G7: =IFERROR(VLOOKUP($F7,'基础-办公用品信息'!$C:$E,2,FALSE),"-") -> 只 | H7: =IFERROR(VLOOKUP($F7,'基础-办公用品信息'!$C:$E,3,FALSE),"-") -> 0 | I7: 2 | J7: =IFERROR(VLOOKUP($F7,'基础-办公用品信息'!$C:$F,4,FALSE),"-") -> 0 | K7: =IFERROR(I7*J7,"") -> 0 | M7: =YEAR(C7) -> 2022 | N7: =MONTH(C7) -> 10
B8: 5 | C8: 44847 | D8: 蔡宏斌 | E8: =IFERROR(VLOOKUP(D8,'基础-领用人及部门'!$C:$D,2,FALSE),"-") -> 综合办 | F8: 活页本芯18K | G8: =IFERROR(VLOOKUP($F8,'基础-办公用品信息'!$C:$E,2,FALSE),"-") -> - | H8: =IFERROR(VLOOKUP($F8,'基础-办公用品信息'!$C:$E,3,FALSE),"-") -> - | I8: 1 | J8: =IFERROR(VLOOKUP($F8,'基础-办公用品信息'!$C:$F,4,FALSE),"-") -> - | K8: =IFERROR(I8*J8,"") | M8: =YEAR(C8) -> 2022 | N8: =MONTH(C8) -> 10
B9: 6 | C9: 44847 | D9: 蔡宏斌 | E9: =IFERROR(VLOOKUP(D9,'基础-领用人及部门'!$C:$D,2,FALSE),"-") -> 综合办 | F9: 医用口罩 | G9: =IFERROR(VLOOKUP($F9,'基础-办公用品信息'!$C:$E,2,FALSE),"-") -> - | H9: =IFERROR(VLOOKUP($F9,'基础-办公用品信息'!$C:$E,3,FALSE),"-") -> - | I9: 1 | J9: =IFERROR(VLOOKUP($F9,'基础-办公用品信息'!$C:$F,4,FALSE),"-") -> - | K9: =IFERROR(I9*J9,"") | M9: =YEAR(C9) -> 2022 | N9: =MONTH(C9) -> 10
B10: 7 | C10: 44848 | D10: 张莉红 | E10: =IFERROR(VLOOKUP(D10,'基础-领用人及部门'!$C:$D,2,FALSE),"-") -> 中盛广场物业 | F10: 笔芯 | G10: =IFERROR(VLOOKUP($F10,'基础-办公用品信息'!$C:$E,2,FALSE),"-") -> 支 | H10: =IFERROR(VLOOKUP($F10,'基础-办公用品信息'!$C:$E,3,FALSE),"-") -> 0 | I10: 12 | J10: =IFERROR(VLOOKUP($F10,'基础-办公用品信息'!$C:$F,4,FALSE),"-") -> 0 | K10: =IFERROR(I10*J10,"") -> 0 | M10: =YEAR(C10) -> 2022 | N10: =MONTH(C10) -> 10
B11: 8 | C11: 44848 | D11: 张莉红 | E11: =IFERROR(VLOOKUP(D11,'基础-领用人及部门'!$C:$D,2,FALSE),"-") -> 中盛广场物业 | F11: 入库单两联 | G11: =IFERROR(VLOOKUP($F11,'基础-办公用品信息'!$C:$E,2,FALSE),"-") -> 本 | H11: =IFERROR(VLOOKUP($F11,'基础-办公用品信息'!$C:$E,3,FALSE),"-") -> 0 | I11: 4 | J11: =IFERROR(VLOOKUP($F11,'基础-办公用品信息'!$C:$F,4,FALSE),"-") -> 0 | K11: =IFERROR(I11*J11,"") -> 0 | M11: =YEAR(C11) -> 2022 | N11: =MONTH(C11) -> 10
B12: 9 | C12: 44848 | D12: 张莉红 | E12: =IFERROR(VLOOKUP(D12,'基础-领用人及部门'!$C:$D,2,FALSE),"-") -> 中盛广场物业 | F12: 水笔黑色 | G12: =IFERROR(VLOOKUP($F12,'基础-办公用品信息'!$C:$E,2,FALSE),"-") -> 支 | H12: =IFERROR(VLOOKUP($F12,'基础-办公用品信息'!$C:$E,3,FALSE),"-") -> 0 | I12: 24 | J12: =IFERROR(VLOOKUP($F12,'基础-办公用品信息'!$C:$F,4,FALSE),"-") -> 1.3 | K12: =IFERROR(I12*J12,"") -> 31.2 | M12: =YEAR(C12) -> 2022 | N12: =MONTH(C12) -> 10
B13: 10 | C13: 44848 | D13: 张莉红 | E13: =IFERROR(VLOOKUP(D13,'基础-领用人及部门'!$C:$D,2,FALSE),"-") -> 中盛广场物业 | F13: 剪刀 | G13: =IFERROR(VLOOKUP($F13,'基础-办公用品信息'!$C:$E,2,FALSE),"-") -> 把 | H13: =IFERROR(VLOOKUP($F13,'基础-办公用品信息'!$C:$E,3,FALSE),"-") -> 0 | I13: 1 | J13: =IFERROR(VLOOKUP($F13,'基础-办公用品信息'!$C:$F,4,FALSE),"-") -> 3.5 | K13: =IFERROR(I13*J13,"") -> 3.5 | M13: =YEAR(C13) -> 2022 | N13: =MONTH(C13) -> 10
B14: 11 | C14: 44848 | D14: 张莉红 | E14: =IFERROR(VLOOKUP(D14,'基础-领用人及部门'!$C:$D,2,FALSE),"-") -> 中盛广场物业 | F14: 报销单 | G14: =IFERROR(VLOOKUP($F14,'基础-办公用品信息'!$C:$E,2,FALSE),"-") -> 本 | H14: =IFERROR(VLOOKUP($F14,'基础-办公用品信息'!$C:$E,3,FALSE),"-") -> 0 | I14: 6 | J14: =IFERROR(VLOOKUP($F14,'基础-办公用品信息'!$C:$F,4,FALSE),"-") -> 1.2 | K14: =IFERROR(I14*J14,"") -> 7.2 | M14: =YEAR(C14) -> 2022 | N14: =MONTH(C14) -> 10
B15: 12 | C15: 44858 | D15: 余光耀 | E15: =IFERROR(VLOOKUP(D15,'基础-领用人及部门'!$C:$D,2,FALSE),"-") -> 成本部 | F15: A3打印纸 | G15: =IFERROR(VLOOKUP($F15,'基础-办公用品信息'!$C:$E,2,FALSE),"-") -> 包 | H15: =IFERROR(VLOOKUP($F15,'基础-办公用品信息'!$C:$E,3,FALSE),"-") -> 0 | I15: 4 | J15: =IFERROR(VLOOKUP($F15,'基础-办公用品信息'!$C:$F,4,FALSE),"-") -> 175 | K15: =IFERROR(I15*J15,"") -> 700 | M15: =YEAR(C15) -> 2022 | N15: =MONTH(C15) -> 10
... B32: 29 | C32: 44866 | D32: 杨 雪 | E32: =IFERROR(VLOOKUP(D32,'基础-领用人及部门'!$C:$D,2,FALSE),"-") -> 综合办 | F32: A4打印纸 | G32: =IFERROR(VLOOKUP($F32,'基础-办公用品信息'!$C:$E,2,FALSE),"-") -> 包 | H32: =IFERROR(VLOOKUP($F32,'基础-办公用品信息'!$C:$E,3,FALSE),"-") -> 0 | I32: 8 | J32: =IFERROR(VLOOKUP($F32,'基础-办公用品信息'!$C:$F,4,FALSE),"-") -> 175 | K32: =IFERROR(I32*J32,"") -> 1400 | M32: =YEAR(C32) -> 2022 | N32: =MONTH(C32) -> 11
B33: 30 | C33: 44865 | D33: 毛总 | E33: boss | F33: 插座5m | G33: =IFERROR(VLOOKUP($F33,'基础-办公用品信息'!$C:$E,2,FALSE),"-") -> 个 | H33: =IFERROR(VLOOKUP($F33,'基础-办公用品信息'!$C:$E,3,FALSE),"-") -> 0 | I33: 1 | J33: =IFERROR(VLOOKUP($F33,'基础-办公用品信息'!$C:$F,4,FALSE),"-") -> 56 | K33: =IFERROR(I33*J33,"") -> 56 | M33: =YEAR(C33) -> 2022 | N33: =MONTH(C33) -> 10
B34: 31 | C34: 44865 | D34: 毛总 | E34: boss | F34: 插座1.8m | G34: =IFERROR(VLOOKUP($F34,'基础-办公用品信息'!$C:$E,2,FALSE),"-") -> 个 | H34: =IFERROR(VLOOKUP($F34,'基础-办公用品信息'!$C:$E,3,FALSE),"-") -> 0 | I34: 1 | J34: =IFERROR(VLOOKUP($F34,'基础-办公用品信息'!$C:$F,4,FALSE),"-") -> 26 | K34: =IFERROR(I34*J34,"") -> 26 | M34: =YEAR(C34) -> 2022 | N34: =MONTH(C34) -> 10
B35: 32 | C35: 44866 | D35: 陈 奔 | E35: =IFERROR(VLOOKUP(D35,'基础-领用人及部门'!$C:$D,2,FALSE),"-") -> 综合办 | F35: office本32k | G35: =IFERROR(VLOOKUP($F35,'基础-办公用品信息'!$C:$E,2,FALSE),"-") -> 本 | H35: =IFERROR(VLOOKUP($F35,'基础-办公用品信息'!$C:$E,3,FALSE),"-") -> 0 | I35: 5 | J35: =IFERROR(VLOOKUP($F35,'基础-办公用品信息'!$C:$F,4,FALSE),"-") -> 0 | K35: =IFERROR(I35*J35,"") -> 0 | M35: =YEAR(C35) -> 2022 | N35: =MONTH(C35) -> 11
B36: 33 | C36: 44866 | D36: 陈璐 | E36: =IFERROR(VLOOKUP(D36,'基础-领用人及部门'!$C:$D,2,FALSE),"-") -> 销售部 | F36: 水笔黑色 | G36: =IFERROR(VLOOKUP($F36,'基础-办公用品信息'!$C:$E,2,FALSE),"-") -> 支 | H36: =IFERROR(VLOOKUP($F36,'基础-办公用品信息'!$C:$E,3,FALSE),"-") -> 0 | I36: 36 | J36: =IFERROR(VLOOKUP($F36,'基础-办公用品信息'!$C:$F,4,FALSE),"-") -> 1.3 | K36: =IFERROR(I36*J36,"") -> 46.8 | M36: =YEAR(C36) -> 2022 | N36: =MONTH(C36) -> 11
B37: 34 | C37: 44866 | D37: 陈璐 | E37: =IFERROR(VLOOKUP(D37,'基础-领用人及部门'!$C:$D,2,FALSE),"-") -> 销售部 | F37: 垃圾袋 | G37: =IFERROR(VLOOKUP($F37,'基础-办公用品信息'!$C:$E,2,FALSE),"-") -> 卷 | H37: =IFERROR(VLOOKUP($F37,'基础-办公用品信息'!$C:$E,3,FALSE),"-") -> 0 | I37: 12 | J37: =IFERROR(VLOOKUP($F37,'基础-办公用品信息'!$C:$F,4,FALSE),"-") -> 0 | K37: =IFERROR(I37*J37,"") -> 0 | M37: =YEAR(C37) -> 2022 | N37: =MONTH(C37) -> 11
B38: 35 | C38: 44866 | D38: 陈璐 | E38: =IFERROR(VLOOKUP(D38,'基础-领用人及部门'!$C:$D,2,FALSE),"-") -> 销售部 | F38: 玻璃刮刀 | G38: =IFERROR(VLOOKUP($F38,'基础-办公用品信息'!$C:$E,2,FALSE),"-") -> 个 | H38: =IFERROR(VLOOKUP($F38,'基础-办公用品信息'!$C:$E,3,FALSE),"-") -> 0 | I38: 1 | J38: =IFERROR(VLOOKUP($F38,'基础-办公用品信息'!$C:$F,4,FALSE),"-") -> 0 | K38: =IFERROR(I38*J38,"") -> 0 | M38: =YEAR(C38) -> 2022 | N38: =MONTH(C38) -> 11
B39: 36 | C39: 44866 | D39: 陈璐 | E39: =IFERROR(VLOOKUP(D39,'基础-领用人及部门'!$C:$D,2,FALSE),"-") -> 销售部 | F39: 拖把 | G39: =IFERROR(VLOOKUP($F39,'基础-办公用品信息'!$C:$E,2,FALSE),"-") -> 个 | H39: =IFERROR(VLOOKUP($F39,'基础-办公用品信息'!$C:$E,3,FALSE),"-") -> 0 | I39: 1 | J39: =IFERROR(VLOOKUP($F39,'基础-办公用品信息'!$C:$F,4,FALSE),"-") -> 0 | K39: =IFERROR(I39*J39,"") -> 0 | M39: =YEAR(C39) -> 2022 | N39: =MONTH(C39) -> 11
B40: 37 | C40: 44866 | D40: 陈璐 | E40: =IFERROR(VLOOKUP(D40,'基础-领用人及部门'!$C:$D,2,FALSE),"-") -> 销售部 | F40: 玻璃水 | G40: =IFERROR(VLOOKUP($F40,'基础-办公用品信息'!$C:$E,2,FALSE),"-") -> 瓶 | H40: =IFERROR(VLOOKUP($F40,'基础-办公用品信息'!$C:$E,3,FALSE),"-") -> 0 | I40: 1 | J40: =IFERROR(VLOOKUP($F40,'基础-办公用品信息'!$C:$F,4,FALSE),"-") -> 0 | K40: =IFERROR(I40*J40,"") -> 0 | M40: =YEAR(C40) -> 2022 | N40: =MONTH(C40) -> 11
B41: 38 | C41: 44866 | D41: 会议室 | E41: =IFERROR(VLOOKUP(D41,'基础-领用人及部门'!$C:$D,2,FALSE),"-") -> 四楼会议室 | F41: 抽纸盒 | G41: =IFERROR(VLOOKUP($F41,'基础-办公用品信息'!$C:$E,2,FALSE),"-") -> 盒 | H41: =IFERROR(VLOOKUP($F41,'基础-办公用品信息'!$C:$E,3,FALSE),"-") -> 0 | I41: 3 | J41: =IFERROR(VLOOKUP($F41,'基础-办公用品信息'!$C:$F,4,FALSE),"-") -> 5.3 | K41: =IFERROR(I41*J41,"") -> 15.9 | M41: =YEAR(C41) -> 2022 | N41: =MONTH(C41) -> 11
B42: 39 | C42: 44866 | D42: 陈璐 | E42: =IFERROR(VLOOKUP(D42,'基础-领用人及部门'!$C:$D,2,FALSE),"-") -> 销售部 | F42: 毛巾 | G42: =IFERROR(VLOOKUP($F42,'基础-办公用品信息'!$C:$E,2,FALSE),"-") -> 条 | H42: =IFERROR(VLOOKUP($F42,'基础-办公用品信息'!$C:$E,3,FALSE),"-") -> 0 | I42: 2 | J42: =IFERROR(VLOOKUP($F42,'基础-办公用品信息'!$C:$F,4,FALSE),"-") -> 0 | K42: =IFERROR(I42*J42,"") -> 0 | M42: =YEAR(C42) -> 2022 | N42: =MONTH(C42) -> 11
B43: 40 | C43: 44866 | D43: 陈璐 | E43: =IFERROR(VLOOKUP(D43,'基础-领用人及部门'!$C:$D,2,FALSE),"-") -> 销售部 | F43: 钉钉打卡机 | G43: =IFERROR(VLOOKUP($F43,'基础-办公用品信息'!$C:$E,2,FALSE),"-") -> 个 | H43: =IFERROR(VLOOKUP($F43,'基础-办公用品信息'!$C:$E,3,FALSE),"-") -> 0 | I43: 1 | J43: =IFERROR(VLOOKUP($F43,'基础-办公用品信息'!$C:$F,4,FALSE),"-") -> 0 | K43: =IFERROR(I43*J43,"") -> 0 | M43: =YEAR(C43) -> 2022 | N43: =MONTH(C43) -> 11
B44: 41 | C44: 44866 | D44: 陈璐 | E44: =IFERROR(VLOOKUP(D44,'基础-领用人及部门'!$C:$D,2,FALSE),"-") -> 销售部 | F44: 酒精消毒水 | G44: =IFERROR(VLOOKUP($F44,'基础-办公用品信息'!$C:$E,2,FALSE),"-") -> 瓶 | H44: =IFERROR(VLOOKUP($F44,'基础-办公用品信息'!$C:$E,3,FALSE),"-") -> 0 | I44: 2 | J44: =IFERROR(VLOOKUP($F44,'基础-办公用品信息'!$C:$F,4,FALSE),"-") -> 0 | K44: =IFERROR(I44*J44,"") -> 0 | M44: =YEAR(C44) -> 2022 | N44: =MONTH(C44) -> 11
B45: 42 | C45: 44868 | D45: 曹家平 | E45: =IFERROR(VLOOKUP(D45,'基础-领用人及部门'!$C:$D,2,FALSE),"-") -> 综合办 | F45: 马桶刷 | G45: =IFERROR(VLOOKUP($F45,'基础-办公用品信息'!$C:$E,2,FALSE),"-") -> 个 | H45: =IFERROR(VLOOKUP($F45,'基础-办公用品信息'!$C:$E,3,FALSE),"-") -> 0 | I45: 2 | J45: =IFERROR(VLOOKUP($F45,'基础-办公用品信息'!$C:$F,4,FALSE),"-") -> 0 | K45: =IFERROR(I45*J45,"") -> 0 | M45: =YEAR(C45) -> 2022 | N45: =MONTH(C45) -> 11
B46: 43 | C46: 44868 | D46: 曹家平 | E46: =IFERROR(VLOOKUP(D46,'基础-领用人及部门'!$C:$D,2,FALSE),"-") -> 综合办 | F46: 垃圾袋 | G46: =IFERROR(VLOOKUP($F46,'基础-办公用品信息'!$C:$E,2,FALSE),"-") -> 卷 | H46: =IFERROR(VLOOKUP($F46,'基础-办公用品信息'!$C:$E,3,FALSE),"-") -> 0 | I46: 15 | J46: =IFERROR(VLOOKUP($F46,'基础-办公用品信息'!$C:$F,4,FALSE),"-") -> 0 | K46: =IFERROR(I46*J46,"") -> 0 | M46: =YEAR(C46) -> 2022 | N46: =MONTH(C46) -> 11
... B94: 91 | C94: 44893 | D94: 王 彪 | E94: =IFERROR(VLOOKUP(D94,'基础-领用人及部门'!$C:$D,2,FALSE),"-") -> 财务部 | F94: 橡皮 | G94: =IFERROR(VLOOKUP($F94,'基础-办公用品信息'!$C:$E,2,FALSE),"-") -> 个 | H94: =IFERROR(VLOOKUP($F94,'基础-办公用品信息'!$C:$E,3,FALSE),"-") -> 0 | I94: 1 | J94: =IFERROR(VLOOKUP($F94,'基础-办公用品信息'!$C:$F,4,FALSE),"-") -> 0 | K94: =IFERROR(I94*J94,"") -> 0 | M94: =YEAR(C94) -> 2022 | N94: =MONTH(C94) -> 11
B95: 92 | C95: 44893 | D95: 王 彪 | E95: =IFERROR(VLOOKUP(D95,'基础-领用人及部门'!$C:$D,2,FALSE),"-") -> 财务部 | F95: 固体胶水 | G95: =IFERROR(VLOOKUP($F95,'基础-办公用品信息'!$C:$E,2,FALSE),"-") -> 支 | H95: =IFERROR(VLOOKUP($F95,'基础-办公用品信息'!$C:$E,3,FALSE),"-") -> 0 | I95: 4 | J95: 5 | K95: =IFERROR(I95*J95,"") -> 20 | M95: =YEAR(C96) -> 2022 | N95: =MONTH(C96) -> 11
B96: 93 | C96: 44893 | D96: 金华鼎 | E96: =IFERROR(VLOOKUP(D96,'基础-领用人及部门'!$C:$D,2,FALSE),"-") -> 技术部 | F96: 交换机 | G96: =IFERROR(VLOOKUP($F96,'基础-办公用品信息'!$C:$E,2,FALSE),"-") -> 个 | H96: =IFERROR(VLOOKUP($F96,'基础-办公用品信息'!$C:$E,3,FALSE),"-") -> 0 | I96: 1 | J96: =IFERROR(VLOOKUP($F96,'[2]基础-G98办公用品信息'!$C:$F,4,FALSE),"-") -> - | K96: =IFERROR(I96*J96,"") | M96: =YEAR(C97) -> 2022 | N96: =MONTH(C97) -> 11
B97: 94 | C97: 44893 | D97: 陶怡然 | E97: =IFERROR(VLOOKUP(D97,'基础-领用人及部门'!$C:$D,2,FALSE),"-") -> 综合办 | F97: 入库单两联 | G97: =IFERROR(VLOOKUP($F97,'基础-办公用品信息'!$C:$E,2,FALSE),"-") -> 本 | H97: =IFERROR(VLOOKUP($F97,'基础-办公用品信息'!$C:$E,3,FALSE),"-") -> 0 | I97: 1 | J97: =IFERROR(VLOOKUP($F97,'基础-办公用品信息'!$C:$F,4,FALSE),"-") -> 0 | K97: =IFERROR(I97*J97,"") -> 0 | M97: =YEAR(#REF!) -> #REF! | N97: =MONTH(#REF!) -> #REF!
B98: 95 | C98: 44893 | D98: 曹家平 | E98: =IFERROR(VLOOKUP(D98,'基础-领用人及部门'!$C:$D,2,FALSE),"-") -> 综合办 | F98: 尘推杆 | G98: =IFERROR(VLOOKUP($F98,'基础-办公用品信息'!$C:$E,2,FALSE),"-") -> 根 | H98: =IFERROR(VLOOKUP($F98,'基础-办公用品信息'!$C:$E,3,FALSE),"-") -> 0 | I98: 1 | J98: =IFERROR(VLOOKUP($F98,'基础-办公用品信息'!$C:$F,4,FALSE),"-") -> 0 | K98: =IFERROR(I98*J98,"") -> 0 | M98: =YEAR(C98) -> 2022 | N98: =MONTH(C98) -> 11
B99: 96 | C99: 44894 | D99: 文丽梅 | E99: =IFERROR(VLOOKUP(D99,'基础-领用人及部门'!$C:$D,2,FALSE),"-") -> 综合办 | F99: 固体胶水 | G99: =IFERROR(VLOOKUP($F99,'基础-办公用品信息'!$C:$E,2,FALSE),"-") -> 支 | H99: =IFERROR(VLOOKUP($F99,'基础-办公用品信息'!$C:$E,3,FALSE),"-") -> 0 | I99: 2 | J99: =IFERROR(VLOOKUP($F99,'基础-办公用品信息'!$C:$F,4,FALSE),"-") -> 1 | K99: =IFERROR(I99*J99,"") -> 2 | M99: =YEAR(C99) -> 2022 | N99: =MONTH(C99) -> 11
B100: 97 | C100: 44894 | D100: 陶怡然 | E100: =IFERROR(VLOOKUP(D100,'基础-领用人及部门'!$C:$D,2,FALSE),"-") -> 综合办 | F100: 固体胶水 | G100: =IFERROR(VLOOKUP($F100,'基础-办公用品信息'!$C:$E,2,FALSE),"-") -> 支 | H100: =IFERROR(VLOOKUP($F100,'基础-办公用品信息'!$C:$E,3,FALSE),"-") -> 0 | I100: 1 | J100: =IFERROR(VLOOKUP($F100,'基础-办公用品信息'!$C:$F,4,FALSE),"-") -> 1 | K100: =IFERROR(I100*J100,"") -> 1 | M100: =YEAR(C100) -> 2022 | N100: =MONTH(C100) -> 11
B101: 98 | C101: 44894 | D101: 陶怡然 | E101: =IFERROR(VLOOKUP(D101,'基础-领用人及部门'!$C:$D,2,FALSE),"-") -> 综合办 | F101: 剪刀 | G101: =IFERROR(VLOOKUP($F101,'基础-办公用品信息'!$C:$E,2,FALSE),"-") -> 把 | H101: =IFERROR(VLOOKUP($F101,'基础-办公用品信息'!$C:$E,3,FALSE),"-") -> 0 | I101: 1 | J101: =IFERROR(VLOOKUP($F101,'基础-办公用品信息'!$C:$F,4,FALSE),"-") -> 3.5 | K101: =IFERROR(I101*J101,"") -> 3.5 | M101: =YEAR(C101) -> 2022 | N101: =MONTH(C101) -> 11
B102: 99 | C102: 44894 | D102: 陶怡然 | E102: =IFERROR(VLOOKUP(D102,'基础-领用人及部门'!$C:$D,2,FALSE),"-") -> 综合办 | F102: A4打印纸 | G102: =IFERROR(VLOOKUP($F102,'基础-办公用品信息'!$C:$E,2,FALSE),"-") -> 包 | H102: =IFERROR(VLOOKUP($F102,'基础-办公用品信息'!$C:$E,3,FALSE),"-") -> 0 | I102: 4 | J102: =IFERROR(VLOOKUP($F102,'基础-办公用品信息'!$C:$F,4,FALSE),"-") -> 175 | K102: =IFERROR(I102*J102,"") -> 700 | M102: =YEAR(C102) -> 2022 | N102: =MONTH(C102) -> 11
B103: 100 | C103: 44895 | D103: 余慧娟 | E103: =IFERROR(VLOOKUP(D103,'基础-领用人及部门'!$C:$D,2,FALSE),"-") -> 综合办 | F103: 电池双鹿7号 | G103: =IFERROR(VLOOKUP($F103,'基础-办公用品信息'!$C:$E,2,FALSE),"-") -> 节 | H103: =IFERROR(VLOOKUP($F103,'基础-办公用品信息'!$C:$E,3,FALSE),"-") -> 0 | I103: 3 | J103: =IFERROR(VLOOKUP($F103,'基础-办公用品信息'!$C:$F,4,FALSE),"-") -> 0 | K103: =IFERROR(I103*J103,"") -> 0 | M103: =YEAR(C103) -> 2022 | N103: =MONTH(C103) -> 11
B104: 101 | C104: 44896 | D104: 陶怡然 | E104: =IFERROR(VLOOKUP(D104,'基础-领用人及部门'!$C:$D,2,FALSE),"-") -> 综合办 | F104: 毛巾 | G104: =IFERROR(VLOOKUP($F104,'基础-办公用品信息'!$C:$E,2,FALSE),"-") -> 条 | H104: =IFERROR(VLOOKUP($F104,'基础-办公用品信息'!$C:$E,3,FALSE),"-") -> 0 | I104: 2 | J104: =IFERROR(VLOOKUP($F104,'基础-办公用品信息'!$C:$F,4,FALSE),"-") -> 0 | K104: =IFERROR(I104*J104,"") -> 0 | M104: =YEAR(C104) -> 2022 | N104: =MONTH(C104) -> 12
...

Sheet 部门领取汇总
B2: 部门领取汇总 | L2: 领取数量 | M2: 领取金额
L3: =SUM(I8:I500) -> 63 | M3: =SUM(K8:K500) -> 84.3
B4: 指定查询的领取部门： | D4: 销售部 | F4: 输入领取的起止日期： | H4: 43466 | I4: 至 | J4: 44925
B6: ="在设定的时间段内查询到 ["&D4&"] 部门记录共"&COUNTIFS(I8:I207,">0.5")&"条；合计数量为"&SUM(I8:I207)&"件" -> 在设定的时间段内查询到 [销售部] 部门记录共11条；合计数量为63件
B7: NO: | C7: 办公用品名称 | E7: 单位 | G7: 型号 | I7: 数量 | J7: 单价 | K7: 金额
B8: 1 | C8: =IF('基础-办公用品信息'!C4="","-",'基础-办公用品信息'!C4) -> A3打印纸 | E8: =IF('基础-办公用品信息'!D4="","-",'基础-办公用品信息'!D4) -> 包 | G8: =IF('基础-办公用品信息'!E4="","-",'基础-办公用品信息'!E4) -> - | I8: =SUMIFS('领用录入（明细）'!I:I,'领用录入（明细）'!E:E,$D$4,'领用录入（明细）'!C:C,">="&$H$4,'领用录入（明细）'!C:C,"<="&$J$4,'领用录入（明细）'!F:F,C8) -> 0 | J8: =IFERROR(VLOOKUP(C8,'基础-办公用品信息'!$C:$G,4,0),"-") -> 175 | K8: =SUMIFS('领用录入（明细）'!K:K,'领用录入（明细）'!E:E,$D$4,'领用录入（明细）'!C:C,">="&$H$4,'领用录入（明细）'!C:C,"<="&$J$4,'领用录入（明细）'!F:F,C8) -> 0
B9: 2 | C9: =IF('基础-办公用品信息'!C5="","-",'基础-办公用品信息'!C5) -> A4打印纸 | E9: =IF('基础-办公用品信息'!D5="","-",'基础-办公用品信息'!D5) -> 包 | G9: =IF('基础-办公用品信息'!E5="","-",'基础-办公用品信息'!E5) -> - | I9: =SUMIFS('领用录入（明细）'!I:I,'领用录入（明细）'!E:E,$D$4,'领用录入（明细）'!C:C,">="&$H$4,'领用录入（明细）'!C:C,"<="&$J$4,'领用录入（明细）'!F:F,C9) -> 0 | J9: =IFERROR(VLOOKUP(C9,'基础-办公用品信息'!$C:$G,4,0),"") -> 175 | K9: =SUMIFS('领用录入（明细）'!K:K,'领用录入（明细）'!E:E,$D$4,'领用录入（明细）'!C:C,">="&$H$4,'领用录入（明细）'!C:C,"<="&$J$4,'领用录入（明细）'!F:F,C9) -> 0
B10: 3 | C10: =IF('基础-办公用品信息'!C6="","-",'基础-办公用品信息'!C6) -> A4装订封面纸 | E10: =IF('基础-办公用品信息'!D6="","-",'基础-办公用品信息'!D6) -> 包 | G10: =IF('基础-办公用品信息'!E6="","-",'基础-办公用品信息'!E6) -> - | I10: =SUMIFS('领用录入（明细）'!I:I,'领用录入（明细）'!E:E,$D$4,'领用录入（明细）'!C:C,">="&$H$4,'领用录入（明细）'!C:C,"<="&$J$4,'领用录入（明细）'!F:F,C10) -> 0 | J10: =IFERROR(VLOOKUP(C10,'基础-办公用品信息'!$C:$G,4,0),"") -> 18 | K10: =SUMIFS('领用录入（明细）'!K:K,'领用录入（明细）'!E:E,$D$4,'领用录入（明细）'!C:C,">="&$H$4,'领用录入（明细）'!C:C,"<="&$J$4,'领用录入（明细）'!F:F,C10) -> 0
B11: 4 | C11: =IF('基础-办公用品信息'!C7="","-",'基础-办公用品信息'!C7) -> A4复印纸蓝色 | E11: =IF('基础-办公用品信息'!D7="","-",'基础-办公用品信息'!D7) -> 包 | G11: =IF('基础-办公用品信息'!E7="","-",'基础-办公用品信息'!E7) -> - | I11: =SUMIFS('领用录入（明细）'!I:I,'领用录入（明细）'!E:E,$D$4,'领用录入（明细）'!C:C,">="&$H$4,'领用录入（明细）'!C:C,"<="&$J$4,'领用录入（明细）'!F:F,C11) -> 0 | J11: =IFERROR(VLOOKUP(C11,'基础-办公用品信息'!$C:$G,4,0),"") -> 0 | K11: =SUMIFS('领用录入（明细）'!K:K,'领用录入（明细）'!E:E,$D$4,'领用录入（明细）'!C:C,">="&$H$4,'领用录入（明细）'!C:C,"<="&$J$4,'领用录入（明细）'!F:F,C11) -> 0
B12: 5 | C12: =IF('基础-办公用品信息'!C8="","-",'基础-办公用品信息'!C8) -> A4复印纸红色 | E12: =IF('基础-办公用品信息'!D8="","-",'基础-办公用品信息'!D8) -> 包 | G12: =IF('基础-办公用品信息'!E8="","-",'基础-办公用品信息'!E8) -> - | I12: =SUMIFS('领用录入（明细）'!I:I,'领用录入（明细）'!E:E,$D$4,'领用录入（明细）'!C:C,">="&$H$4,'领用录入（明细）'!C:C,"<="&$J$4,'领用录入（明细）'!F:F,C12) -> 0 | J12: =IFERROR(VLOOKUP(C12,'基础-办公用品信息'!$C:$G,4,0),"") -> 0 | K12: =SUMIFS('领用录入（明细）'!K:K,'领用录入（明细）'!E:E,$D$4,'领用录入（明细）'!C:C,">="&$H$4,'领用录入（明细）'!C:C,"<="&$J$4,'领用录入（明细）'!F:F,C12) -> 0
B13: 6 | C13: =IF('基础-办公用品信息'!C9="","-",'基础-办公用品信息'!C9) -> A4白卡纸180克荷兰白卡 | E13: =IF('基础-办公用品信息'!D9="","-",'基础-办公用品信息'!D9) -> 包 | G13: =IF('基础-办公用品信息'!E9="","-",'基础-办公用品信息'!E9) -> - | I13: =SUMIFS('领用录入（明细）'!I:I,'领用录入（明细）'!E:E,$D$4,'领用录入（明细）'!C:C,">="&$H$4,'领用录入（明细）'!C:C,"<="&$J$4,'领用录入（明细）'!F:F,C13) -> 0 | J13: =IFERROR(VLOOKUP(C13,'基础-办公用品信息'!$C:$G,4,0),"") -> 0 | K13: =SUMIFS('领用录入（明细）'!K:K,'领用录入（明细）'!E:E,$D$4,'领用录入（明细）'!C:C,">="&$H$4,'领用录入（明细）'!C:C,"<="&$J$4,'领用录入（明细）'!F:F,C13) -> 0
B14: 7 | C14: =IF('基础-办公用品信息'!C10="","-",'基础-办公用品信息'!C10) -> 定制会议本牛皮A4 | E14: =IF('基础-办公用品信息'!D10="","-",'基础-办公用品信息'!D10) -> 本 | G14: =IF('基础-办公用品信息'!E10="","-",'基础-办公用品信息'!E10) -> - | I14: =SUMIFS('领用录入（明细）'!I:I,'领用录入（明细）'!E:E,$D$4,'领用录入（明细）'!C:C,">="&$H$4,'领用录入（明细）'!C:C,"<="&$J$4,'领用录入（明细）'!F:F,C14) -> 0 | J14: =IFERROR(VLOOKUP(C14,'基础-办公用品信息'!$C:$G,4,0),"") -> 0 | K14: =SUMIFS('领用录入（明细）'!K:K,'领用录入（明细）'!E:E,$D$4,'领用录入（明细）'!C:C,">="&$H$4,'领用录入（明细）'!C:C,"<="&$J$4,'领用录入（明细）'!F:F,C14) -> 0
B15: 8 | C15: =IF('基础-办公用品信息'!C11="","-",'基础-办公用品信息'!C11) -> 定制会议本活页B5 | E15: =IF('基础-办公用品信息'!D11="","-",'基础-办公用品信息'!D11) -> 本 | G15: =IF('基础-办公用品信息'!E11="","-",'基础-办公用品信息'!E11) -> - | I15: =SUMIFS('领用录入（明细）'!I:I,'领用录入（明细）'!E:E,$D$4,'领用录入（明细）'!C:C,">="&$H$4,'领用录入（明细）'!C:C,"<="&$J$4,'领用录入（明细）'!F:F,C15) -> 0 | J15: =IFERROR(VLOOKUP(C15,'基础-办公用品信息'!$C:$G,4,0),"") -> 0 | K15: =SUMIFS('领用录入（明细）'!K:K,'领用录入（明细）'!E:E,$D$4,'领用录入（明细）'!C:C,">="&$H$4,'领用录入（明细）'!C:C,"<="&$J$4,'领用录入（明细）'!F:F,C15) -> 0
B16: 9 | C16: =IF('基础-办公用品信息'!C12="","-",'基础-办公用品信息'!C12) -> 定制会议便签本牛皮书写夹板A4 | E16: =IF('基础-办公用品信息'!D12="","-",'基础-办公用品信息'!D12) -> 本 | G16: =IF('基础-办公用品信息'!E12="","-",'基础-办公用品信息'!E12) -> - | I16: =SUMIFS('领用录入（明细）'!I:I,'领用录入（明细）'!E:E,$D$4,'领用录入（明细）'!C:C,">="&$H$4,'领用录入（明细）'!C:C,"<="&$J$4,'领用录入（明细）'!F:F,C16) -> 0 | J16: =IFERROR(VLOOKUP(C16,'基础-办公用品信息'!$C:$G,4,0),"") -> 0 | K16: =SUMIFS('领用录入（明细）'!K:K,'领用录入（明细）'!E:E,$D$4,'领用录入（明细）'!C:C,">="&$H$4,'领用录入（明细）'!C:C,"<="&$J$4,'领用录入（明细）'!F:F,C16) -> 0
B17: 10 | C17: =IF('基础-办公用品信息'!C13="","-",'基础-办公用品信息'!C13) -> 会议记录本皮面黑色 | E17: =IF('基础-办公用品信息'!D13="","-",'基础-办公用品信息'!D13) -> 本 | G17: =IF('基础-办公用品信息'!E13="","-",'基础-办公用品信息'!E13) -> - | I17: =SUMIFS('领用录入（明细）'!I:I,'领用录入（明细）'!E:E,$D$4,'领用录入（明细）'!C:C,">="&$H$4,'领用录入（明细）'!C:C,"<="&$J$4,'领用录入（明细）'!F:F,C17) -> 5 | J17: =IFERROR(VLOOKUP(C17,'基础-办公用品信息'!$C:$G,4,0),"") -> 7.5 | K17: =SUMIFS('领用录入（明细）'!K:K,'领用录入（明细）'!E:E,$D$4,'领用录入（明细）'!C:C,">="&$H$4,'领用录入（明细）'!C:C,"<="&$J$4,'领用录入（明细）'!F:F,C17) -> 37.5
B18: 11 | C18: =IF('基础-办公用品信息'!C14="","-",'基础-办公用品信息'!C14) -> office本32k | E18: =IF('基础-办公用品信息'!D14="","-",'基础-办公用品信息'!D14) -> 本 | G18: =IF('基础-办公用品信息'!E14="","-",'基础-办公用品信息'!E14) -> - | I18: =SUMIFS('领用录入（明细）'!I:I,'领用录入（明细）'!E:E,$D$4,'领用录入（明细）'!C:C,">="&$H$4,'领用录入（明细）'!C:C,"<="&$J$4,'领用录入（明细）'!F:F,C18) -> 0 | J18: =IFERROR(VLOOKUP(C18,'基础-办公用品信息'!$C:$G,4,0),"") -> 0 | K18: =SUMIFS('领用录入（明细）'!K:K,'领用录入（明细）'!E:E,$D$4,'领用录入（明细）'!C:C,">="&$H$4,'领用录入（明细）'!C:C,"<="&$J$4,'领用录入（明细）'!F:F,C18) -> 0
B19: 12 | C19: =IF('基础-办公用品信息'!C15="","-",'基础-办公用品信息'!C15) -> 软面抄100 | E19: =IF('基础-办公用品信息'!D15="","-",'基础-办公用品信息'!D15) -> 本 | G19: =IF('基础-办公用品信息'!E15="","-",'基础-办公用品信息'!E15) -> - | I19: =SUMIFS('领用录入（明细）'!I:I,'领用录入（明细）'!E:E,$D$4,'领用录入（明细）'!C:C,">="&$H$4,'领用录入（明细）'!C:C,"<="&$J$4,'领用录入（明细）'!F:F,C19) -> 0 | J19: =IFERROR(VLOOKUP(C19,'基础-办公用品信息'!$C:$G,4,0),"") -> 1.5 | K19: =SUMIFS('领用录入（明细）'!K:K,'领用录入（明细）'!E:E,$D$4,'领用录入（明细）'!C:C,">="&$H$4,'领用录入（明细）'!C:C,"<="&$J$4,'领用录入（明细）'!F:F,C19) -> 0
B20: 13 | C20: =IF('基础-办公用品信息'!C16="","-",'基础-办公用品信息'!C16) -> 透明暗扣袋 | E20: =IF('基础-办公用品信息'!D16="","-",'基础-办公用品信息'!D16) -> 个 | G20: =IF('基础-办公用品信息'!E16="","-",'基础-办公用品信息'!E16) -> - | I20: =SUMIFS('领用录入（明细）'!I:I,'领用录入（明细）'!E:E,$D$4,'领用录入（明细）'!C:C,">="&$H$4,'领用录入（明细）'!C:C,"<="&$J$4,'领用录入（明细）'!F:F,C20) -> 0 | J20: =IFERROR(VLOOKUP(C20,'基础-办公用品信息'!$C:$G,4,0),"") -> 0 | K20: =SUMIFS('领用录入（明细）'!K:K,'领用录入（明细）'!E:E,$D$4,'领用录入（明细）'!C:C,">="&$H$4,'领用录入（明细）'!C:C,"<="&$J$4,'领用录入（明细）'!F:F,C20) -> 0
... B150: 143 | C150: =IF('基础-办公用品信息'!C146="","-",'基础-办公用品信息'!C146) -> 500消毒液 | E150: =IF('基础-办公用品信息'!D146="","-",'基础-办公用品信息'!D146) -> 瓶 | G150: =IF('基础-办公用品信息'!E146="","-",'基础-办公用品信息'!E146) -> - | I150: =SUMIFS('领用录入（明细）'!I:I,'领用录入（明细）'!E:E,$D$4,'领用录入（明细）'!C:C,">="&$H$4,'领用录入（明细）'!C:C,"<="&$J$4,'领用录入（明细）'!F:F,C150) -> 0 | J150: =IFERROR(VLOOKUP(C150,'基础-办公用品信息'!$C:$G,4,0),"") -> 0 | K150: =SUMIFS('领用录入（明细）'!K:K,'领用录入（明细）'!E:E,$D$4,'领用录入（明细）'!C:C,">="&$H$4,'领用录入（明细）'!C:C,"<="&$J$4,'领用录入（明细）'!F:F,C150) -> 0
B151: 144 | C151: =IF('基础-办公用品信息'!#REF!="","-",'基础-办公用品信息'!#REF!) -> #REF! | E151: =IF('基础-办公用品信息'!#REF!="","-",'基础-办公用品信息'!#REF!) -> #REF! | G151: =IF('基础-办公用品信息'!#REF!="","-",'基础-办公用品信息'!#REF!) -> #REF! | I151: =SUMIFS('领用录入（明细）'!I:I,'领用录入（明细）'!E:E,$D$4,'领用录入（明细）'!C:C,">="&$H$4,'领用录入（明细）'!C:C,"<="&$J$4,'领用录入（明细）'!F:F,C151) -> 0 | J151: =IFERROR(VLOOKUP(C151,'基础-办公用品信息'!$C:$G,4,0),"") | K151: =SUMIFS('领用录入（明细）'!K:K,'领用录入（明细）'!E:E,$D$4,'领用录入（明细）'!C:C,">="&$H$4,'领用录入（明细）'!C:C,"<="&$J$4,'领用录入（明细）'!F:F,C151) -> 0
B152: 145 | C152: =IF('基础-办公用品信息'!C147="","-",'基础-办公用品信息'!C147) -> 拖把 | E152: =IF('基础-办公用品信息'!D147="","-",'基础-办公用品信息'!D147) -> 个 | G152: =IF('基础-办公用品信息'!E147="","-",'基础-办公用品信息'!E147) -> - | I152: =SUMIFS('领用录入（明细）'!I:I,'领用录入（明细）'!E:E,$D$4,'领用录入（明细）'!C:C,">="&$H$4,'领用录入（明细）'!C:C,"<="&$J$4,'领用录入（明细）'!F:F,C152) -> 1 | J152: =IFERROR(VLOOKUP(C152,'基础-办公用品信息'!$C:$G,4,0),"") -> 0 | K152: =SUMIFS('领用录入（明细）'!K:K,'领用录入（明细）'!E:E,$D$4,'领用录入（明细）'!C:C,">="&$H$4,'领用录入（明细）'!C:C,"<="&$J$4,'领用录入（明细）'!F:F,C152) -> 0
B153: 146 | C153: =IF('基础-办公用品信息'!C148="","-",'基础-办公用品信息'!C148) -> 玻璃刮刀 | E153: =IF('基础-办公用品信息'!D148="","-",'基础-办公用品信息'!D148) -> 个 | G153: =IF('基础-办公用品信息'!E148="","-",'基础-办公用品信息'!E148) -> - | I153: =SUMIFS('领用录入（明细）'!I:I,'领用录入（明细）'!E:E,$D$4,'领用录入（明细）'!C:C,">="&$H$4,'领用录入（明细）'!C:C,"<="&$J$4,'领用录入（明细）'!F:F,C153) -> 1 | J153: =IFERROR(VLOOKUP(C153,'基础-办公用品信息'!$C:$G,4,0),"") -> 0 | K153: =SUMIFS('领用录入（明细）'!K:K,'领用录入（明细）'!E:E,$D$4,'领用录入（明细）'!C:C,">="&$H$4,'领用录入（明细）'!C:C,"<="&$J$4,'领用录入（明细）'!F:F,C153) -> 0
B154: 147 | C154: =IF('基础-办公用品信息'!C149="","-",'基础-办公用品信息'!C149) -> 玻璃水 | E154: =IF('基础-办公用品信息'!D149="","-",'基础-办公用品信息'!D149) -> 瓶 | G154: =IF('基础-办公用品信息'!E149="","-",'基础-办公用品信息'!E149) -> - | I154: =SUMIFS('领用录入（明细）'!I:I,'领用录入（明细）'!E:E,$D$4,'领用录入（明细）'!C:C,">="&$H$4,'领用录入（明细）'!C:C,"<="&$J$4,'领用录入（明细）'!F:F,C154) -> 1 | J154: =IFERROR(VLOOKUP(C154,'基础-办公用品信息'!$C:$G,4,0),"") -> 0 | K154: =SUMIFS('领用录入（明细）'!K:K,'领用录入（明细）'!E:E,$D$4,'领用录入（明细）'!C:C,">="&$H$4,'领用录入（明细）'!C:C,"<="&$J$4,'领用录入（明细）'!F:F,C154) -> 0
B155: 148 | C155: =IF('基础-办公用品信息'!C150="","-",'基础-办公用品信息'!C150) -> 毛巾 | E155: =IF('基础-办公用品信息'!D150="","-",'基础-办公用品信息'!D150) -> 条 | G155: =IF('基础-办公用品信息'!E150="","-",'基础-办公用品信息'!E150) -> - | I155: =SUMIFS('领用录入（明细）'!I:I,'领用录入（明细）'!E:E,$D$4,'领用录入（明细）'!C:C,">="&$H$4,'领用录入（明细）'!C:C,"<="&$J$4,'领用录入（明细）'!F:F,C155) -> 2 | J155: =IFERROR(VLOOKUP(C155,'基础-办公用品信息'!$C:$G,4,0),"") -> 0 | K155: =SUMIFS('领用录入（明细）'!K:K,'领用录入（明细）'!E:E,$D$4,'领用录入（明细）'!C:C,">="&$H$4,'领用录入（明细）'!C:C,"<="&$J$4,'领用录入（明细）'!F:F,C155) -> 0
B156: 149 | C156: =IF('基础-办公用品信息'!C151="","-",'基础-办公用品信息'!C151) -> 钉钉打卡机 | E156: =IF('基础-办公用品信息'!D151="","-",'基础-办公用品信息'!D151) -> 个 | G156: =IF('基础-办公用品信息'!E151="","-",'基础-办公用品信息'!E151) -> - | I156: =SUMIFS('领用录入（明细）'!I:I,'领用录入（明细）'!E:E,$D$4,'领用录入（明细）'!C:C,">="&$H$4,'领用录入（明细）'!C:C,"<="&$J$4,'领用录入（明细）'!F:F,C156) -> 1 | J156: =IFERROR(VLOOKUP(C156,'基础-办公用品信息'!$C:$G,4,0),"") -> 0 | K156: =SUMIFS('领用录入（明细）'!K:K,'领用录入（明细）'!E:E,$D$4,'领用录入（明细）'!C:C,">="&$H$4,'领用录入（明细）'!C:C,"<="&$J$4,'领用录入（明细）'!F:F,C156) -> 0
B157: 150 | C157: =IF('基础-办公用品信息'!C152="","-",'基础-办公用品信息'!C152) -> 酒精消毒水 | E157: =IF('基础-办公用品信息'!D152="","-",'基础-办公用品信息'!D152) -> 瓶 | G157: =IF('基础-办公用品信息'!E152="","-",'基础-办公用品信息'!E152) -> - | I157: =SUMIFS('领用录入（明细）'!I:I,'领用录入（明细）'!E:E,$D$4,'领用录入（明细）'!C:C,">="&$H$4,'领用录入（明细）'!C:C,"<="&$J$4,'领用录入（明细）'!F:F,C157) -> 2 | J157: =IFERROR(VLOOKUP(C157,'基础-办公用品信息'!$C:$G,4,0),"") -> 0 | K157: =SUMIFS('领用录入（明细）'!K:K,'领用录入（明细）'!E:E,$D$4,'领用录入（明细）'!C:C,">="&$H$4,'领用录入（明细）'!C:C,"<="&$J$4,'领用录入（明细）'!F:F,C157) -> 0
B158: 151 | C158: =IF('基础-办公用品信息'!C153="","-",'基础-办公用品信息'!C153) -> 马桶刷 | E158: =IF('基础-办公用品信息'!D153="","-",'基础-办公用品信息'!D153) -> 个 | G158: =IF('基础-办公用品信息'!E153="","-",'基础-办公用品信息'!E153) -> - | I158: =SUMIFS('领用录入（明细）'!I:I,'领用录入（明细）'!E:E,$D$4,'领用录入（明细）'!C:C,">="&$H$4,'领用录入（明细）'!C:C,"<="&$J$4,'领用录入（明细）'!F:F,C158) -> 0 | J158: =IFERROR(VLOOKUP(C158,'基础-办公用品信息'!$C:$G,4,0),"") -> 0 | K158: =SUMIFS('领用录入（明细）'!K:K,'领用录入（明细）'!E:E,$D$4,'领用录入（明细）'!C:C,">="&$H$4,'领用录入（明细）'!C:C,"<="&$J$4,'领用录入（明细）'!F:F,C158) -> 0
B159: 152 | C159: =IF('基础-办公用品信息'!C154="","-",'基础-办公用品信息'!C154) -> 洗手液 | E159: =IF('基础-办公用品信息'!D154="","-",'基础-办公用品信息'!D154) -> 瓶 | G159: =IF('基础-办公用品信息'!E154="","-",'基础-办公用品信息'!E154) -> - | I159: =SUMIFS('领用录入（明细）'!I:I,'领用录入（明细）'!E:E,$D$4,'领用录入（明细）'!C:C,">="&$H$4,'领用录入（明细）'!C:C,"<="&$J$4,'领用录入（明细）'!F:F,C159) -> 0 | J159: =IFERROR(VLOOKUP(C159,'基础-办公用品信息'!$C:$G,4,0),"") -> 0 | K159: =SUMIFS('领用录入（明细）'!K:K,'领用录入（明细）'!E:E,$D$4,'领用录入（明细）'!C:C,">="&$H$4,'领用录入（明细）'!C:C,"<="&$J$4,'领用录入（明细）'!F:F,C159) -> 0
B160: 153 | C160: =IF('基础-办公用品信息'!C155="","-",'基础-办公用品信息'!C155) -> 报销单 | E160: =IF('基础-办公用品信息'!D155="","-",'基础-办公用品信息'!D155) -> 本 | G160: =IF('基础-办公用品信息'!E155="","-",'基础-办公用品信息'!E155) -> - | I160: =SUMIFS('领用录入（明细）'!I:I,'领用录入（明细）'!E:E,$D$4,'领用录入（明细）'!C:C,">="&$H$4,'领用录入（明细）'!C:C,"<="&$J$4,'领用录入（明细）'!F:F,C160) -> 0 | J160: =IFERROR(VLOOKUP(C160,'基础-办公用品信息'!$C:$G,4,0),"") -> 1.2 | K160: =SUMIFS('领用录入（明细）'!K:K,'领用录入（明细）'!E:E,$D$4,'领用录入（明细）'!C:C,">="&$H$4,'领用录入（明细）'!C:C,"<="&$J$4,'领用录入（明细）'!F:F,C160) -> 0
B161: 154 | C161: =IF('基础-办公用品信息'!C156="","-",'基础-办公用品信息'!C156) -> 手套 | E161: =IF('基础-办公用品信息'!D156="","-",'基础-办公用品信息'!D156) -> 双 | G161: =IF('基础-办公用品信息'!E156="","-",'基础-办公用品信息'!E156) -> - | I161: =SUMIFS('领用录入（明细）'!I:I,'领用录入（明细）'!E:E,$D$4,'领用录入（明细）'!C:C,">="&$H$4,'领用录入（明细）'!C:C,"<="&$J$4,'领用录入（明细）'!F:F,C161) -> 0 | J161: =IFERROR(VLOOKUP(C161,'基础-办公用品信息'!$C:$G,4,0),"") -> 0 | K161: =SUMIFS('领用录入（明细）'!K:K,'领用录入（明细）'!E:E,$D$4,'领用录入（明细）'!C:C,">="&$H$4,'领用录入（明细）'!C:C,"<="&$J$4,'领用录入（明细）'!F:F,C161) -> 0
B162: 155 | C162: =IF('基础-办公用品信息'!C157="","-",'基础-办公用品信息'!C157) -> 安全帽 | E162: =IF('基础-办公用品信息'!D157="","-",'基础-办公用品信息'!D157) -> 顶 | G162: =IF('基础-办公用品信息'!E157="","-",'基础-办公用品信息'!E157) -> - | I162: =SUMIFS('领用录入（明细）'!I:I,'领用录入（明细）'!E:E,$D$4,'领用录入（明细）'!C:C,">="&$H$4,'领用录入（明细）'!C:C,"<="&$J$4,'领用录入（明细）'!F:F,C162) -> 0 | J162: =IFERROR(VLOOKUP(C162,'基础-办公用品信息'!$C:$G,4,0),"") -> 0 | K162: =SUMIFS('领用录入（明细）'!K:K,'领用录入（明细）'!E:E,$D$4,'领用录入（明细）'!C:C,">="&$H$4,'领用录入（明细）'!C:C,"<="&$J$4,'领用录入（明细）'!F:F,C162) -> 0
B163: 156 | C163: =IF('基础-办公用品信息'!C158="","-",'基础-办公用品信息'!C158) -> 扫把 | E163: =IF('基础-办公用品信息'!D158="","-",'基础-办公用品信息'!D158) -> 把 | G163: =IF('基础-办公用品信息'!E158="","-",'基础-办公用品信息'!E158) -> - | I163: =SUMIFS('领用录入（明细）'!I:I,'领用录入（明细）'!E:E,$D$4,'领用录入（明细）'!C:C,">="&$H$4,'领用录入（明细）'!C:C,"<="&$J$4,'领用录入（明细）'!F:F,C163) -> 1 | J163: =IFERROR(VLOOKUP(C163,'基础-办公用品信息'!$C:$G,4,0),"") -> 0 | K163: =SUMIFS('领用录入（明细）'!K:K,'领用录入（明细）'!E:E,$D$4,'领用录入（明细）'!C:C,">="&$H$4,'领用录入（明细）'!C:C,"<="&$J$4,'领用录入（明细）'!F:F,C163) -> 0
... B207: 200 | C207: =IF('基础-办公用品信息'!C202="","-",'基础-办公用品信息'!C202) -> 白色圆桶 | E207: =IF('基础-办公用品信息'!D202="","-",'基础-办公用品信息'!D202) -> 个 | G207: =IF('基础-办公用品信息'!E202="","-",'基础-办公用品信息'!E202) -> - | I207: =SUMIFS('领用录入（明细）'!I:I,'领用录入（明细）'!E:E,$D$4,'领用录入（明细）'!C:C,">="&$H$4,'领用录入（明细）'!C:C,"<="&$J$4,'领用录入（明细）'!F:F,C207) -> 0 | J207: =IFERROR(VLOOKUP(C207,'基础-办公用品信息'!$C:$G,4,0),"") -> 0 | K207: =SUMIFS('领用录入（明细）'!K:K,'领用录入（明细）'!E:E,$D$4,'领用录入（明细）'!C:C,">="&$H$4,'领用录入（明细）'!C:C,"<="&$J$4,'领用录入（明细）'!F:F,C207) -> 0
C208: =IF('基础-办公用品信息'!C203="","-",'基础-办公用品信息'!C203) -> 地面刮水器 | E208: =IF('基础-办公用品信息'!D203="","-",'基础-办公用品信息'!D203) -> 个 | G208: =IF('基础-办公用品信息'!E203="","-",'基础-办公用品信息'!E203) -> -
C209: =IF('基础-办公用品信息'!C193="","-",'基础-办公用品信息'!C193) -> 格来德烧水壶 | E209: =IF('基础-办公用品信息'!D204="","-",'基础-办公用品信息'!D204) -> 个 | G209: =IF('基础-办公用品信息'!E204="","-",'基础-办公用品信息'!E204) -> -
C210: =IF('基础-办公用品信息'!C194="","-",'基础-办公用品信息'!C194) -> 304欧式保温壶 | E210: =IF('基础-办公用品信息'!D205="","-",'基础-办公用品信息'!D205) -> 个 | G210: =IF('基础-办公用品信息'!E205="","-",'基础-办公用品信息'!E205) -> -
C211: =IF('基础-办公用品信息'!C195="","-",'基础-办公用品信息'!C195) -> 高压锅橡皮圈 | E211: =IF('基础-办公用品信息'!D206="","-",'基础-办公用品信息'!D206) -> 个 | G211: =IF('基础-办公用品信息'!E206="","-",'基础-办公用品信息'!E206) -> -
C212: =IF('基础-办公用品信息'!C196="","-",'基础-办公用品信息'!C196) -> 高压锅橡皮圈 | E212: =IF('基础-办公用品信息'!D207="","-",'基础-办公用品信息'!D207) -> 个 | G212: =IF('基础-办公用品信息'!E207="","-",'基础-办公用品信息'!E207) -> -
C213: =IF('基础-办公用品信息'!C197="","-",'基础-办公用品信息'!C197) -> 高压锅排气阀 | E213: =IF('基础-办公用品信息'!D208="","-",'基础-办公用品信息'!D208) -> 个 | G213: =IF('基础-办公用品信息'!E208="","-",'基础-办公用品信息'!E208) -> -
C214: =IF('基础-办公用品信息'!C198="","-",'基础-办公用品信息'!C198) -> 不锈钢方形冲孔盘 | E214: =IF('基础-办公用品信息'!D209="","-",'基础-办公用品信息'!D209) -> 个 | G214: =IF('基础-办公用品信息'!E209="","-",'基础-办公用品信息'!E209) -> -
...

Sheet 个人领取明细
B2: 辅助列 | D2: 个人领取明细 | N2: 领取数量 | O2: 领取金额
B3: =IF(AND('领用录入（明细）'!D:D=$F$4,'领用录入（明细）'!C:C>=$J$4,'领用录入（明细）'!C:C<=$L$4),ROW(),"-") -> - | N3: =SUM(K8:K1000) -> 35 | O3: =SUM(M8:M1000) -> 83.3
B4: =IF(AND('领用录入（明细）'!D:D=$F$4,'领用录入（明细）'!C:C>=$J$4,'领用录入（明细）'!C:C<=$L$4),ROW(),"-") -> - | D4: 指定查询的领取人： | F4: 余慧娟 | H4: 输入领取的起止日期： | J4: 43466 | K4: 至 | L4: 45291
B5: =IF(AND('领用录入（明细）'!D:D=$F$4,'领用录入（明细）'!C:C>=$J$4,'领用录入（明细）'!C:C<=$L$4),ROW(),"-") -> -
B6: =IF(AND('领用录入（明细）'!D:D=$F$4,'领用录入（明细）'!C:C>=$J$4,'领用录入（明细）'!C:C<=$L$4),ROW(),"-") -> - | D6: ="在设定的时间段内查询到 ["&F4&"] 的记录共"&COUNT(D7:D507)&"条；合计数量为"&SUM(K8:K507)&"件" -> 在设定的时间段内查询到 [余慧娟] 的记录共16条；合计数量为35件
B7: =IF(AND('领用录入（明细）'!D:D=$F$4,'领用录入（明细）'!C:C>=$J$4,'领用录入（明细）'!C:C<=$L$4),ROW(),"-") -> - | D7: NO: | E7: 日期 | F7: 领用人 | G7: 所属部门 | H7: 办公用品名称 | I7: 单位 | J7: 型号 | K7: 数量 | L7: 单价 | M7: 金额
B8: =IF(AND('领用录入（明细）'!D:D=$F$4,'领用录入（明细）'!C:C>=$J$4,'领用录入（明细）'!C:C<=$L$4),ROW(),"-") -> - | D8: =IFERROR(INDEX('领用录入（明细）'!$B:$L,SMALL($B:$B,ROW(B1)),MATCH(D$7,$D$7:$L$7,0)),"") -> 14 | E8: =IFERROR(INDEX('领用录入（明细）'!$B:$L,SMALL($B:$B,ROW(C1)),MATCH(E$7,$D$7:$L$7,0)),"") -> 44858 | F8: =IFERROR(INDEX('领用录入（明细）'!$B:$N,SMALL($B:$B,ROW(D1)),MATCH(F$7,$D$7:$L$7,0)),"") -> 余慧娟 | G8: =IFERROR(INDEX('领用录入（明细）'!$B:$N,SMALL($B:$B,ROW(E1)),MATCH(G$7,$D$7:$L$7,0)),"") -> 综合办 | H8: =IFERROR(INDEX('领用录入（明细）'!$B:$N,SMALL($B:$B,ROW(F1)),MATCH(H$7,$D$7:$L$7,0)),"") -> 蓝色口罩 | I8: =IFERROR(INDEX('领用录入（明细）'!$B:$N,SMALL($B:$B,ROW(G1)),MATCH(I$7,$D$7:$L$7,0)),"") -> 包 | J8: =IFERROR(INDEX('领用录入（明细）'!$B:$N,SMALL($B:$B,ROW(H1)),MATCH(J$7,$D$7:$L$7,0)),"") -> 0 | K8: =IFERROR(INDEX('领用录入（明细）'!$B:$N,SMALL($B:$B,ROW(I1)),MATCH(K$7,$D$7:$L$7,0)),"") -> 5 | L8: =IFERROR(INDEX('领用录入（明细）'!$B:$N,SMALL($B:$B,ROW(J1)),MATCH(L$7,$D$7:$L$7,0)),"") -> 0.3 | M8: =IFERROR(K8*L8,"") -> 1.5
B9: =IF(AND('领用录入（明细）'!D:D=$F$4,'领用录入（明细）'!C:C>=$J$4,'领用录入（明细）'!C:C<=$L$4),ROW(),"-") -> - | D9: =IFERROR(INDEX('领用录入（明细）'!$B:$L,SMALL($B:$B,ROW(B2)),MATCH(D$7,$D$7:$L$7,0)),"") -> 15 | E9: =IFERROR(INDEX('领用录入（明细）'!$B:$L,SMALL($B:$B,ROW(C2)),MATCH(E$7,$D$7:$L$7,0)),"") -> 44858 | F9: =IFERROR(INDEX('领用录入（明细）'!$B:$L,SMALL($B:$B,ROW(D2)),MATCH(F$7,$D$7:$L$7,0)),"") -> 余慧娟 | G9: =IFERROR(INDEX('领用录入（明细）'!$B:$L,SMALL($B:$B,ROW(E2)),MATCH(G$7,$D$7:$L$7,0)),"") -> 综合办 | H9: =IFERROR(INDEX('领用录入（明细）'!$B:$L,SMALL($B:$B,ROW(F2)),MATCH(H$7,$D$7:$L$7,0)),"") -> 封箱胶带 | I9: =IFERROR(INDEX('领用录入（明细）'!$B:$L,SMALL($B:$B,ROW(G2)),MATCH(I$7,$D$7:$L$7,0)),"") -> 筒 | J9: =IFERROR(INDEX('领用录入（明细）'!$B:$L,SMALL($B:$B,ROW(H2)),MATCH(J$7,$D$7:$L$7,0)),"") -> 0 | K9: =IFERROR(INDEX('领用录入（明细）'!$B:$L,SMALL($B:$B,ROW(I2)),MATCH(K$7,$D$7:$L$7,0)),"") -> 1 | L9: =IFERROR(INDEX('领用录入（明细）'!$B:$L,SMALL($B:$B,ROW(J2)),MATCH(L$7,$D$7:$L$7,0)),"") -> 7 | M9: =IFERROR(K9*L9,"") -> 7
B10: =IF(AND('领用录入（明细）'!D:D=$F$4,'领用录入（明细）'!C:C>=$J$4,'领用录入（明细）'!C:C<=$L$4),ROW(),"-") -> - | D10: =IFERROR(INDEX('领用录入（明细）'!$B:$L,SMALL($B:$B,ROW(B3)),MATCH(D$7,$D$7:$L$7,0)),"") -> 16 | E10: =IFERROR(INDEX('领用录入（明细）'!$B:$L,SMALL($B:$B,ROW(C3)),MATCH(E$7,$D$7:$L$7,0)),"") -> 44858 | F10: =IFERROR(INDEX('领用录入（明细）'!$B:$L,SMALL($B:$B,ROW(D3)),MATCH(F$7,$D$7:$L$7,0)),"") -> 余慧娟 | G10: =IFERROR(INDEX('领用录入（明细）'!$B:$L,SMALL($B:$B,ROW(E3)),MATCH(G$7,$D$7:$L$7,0)),"") -> 综合办 | H10: =IFERROR(INDEX('领用录入（明细）'!$B:$L,SMALL($B:$B,ROW(F3)),MATCH(H$7,$D$7:$L$7,0)),"") -> 地毯胶 | I10: =IFERROR(INDEX('领用录入（明细）'!$B:$L,SMALL($B:$B,ROW(G3)),MATCH(I$7,$D$7:$L$7,0)),"") -> 个 | J10: =IFERROR(INDEX('领用录入（明细）'!$B:$L,SMALL($B:$B,ROW(H3)),MATCH(J$7,$D$7:$L$7,0)),"") -> 0 | K10: =IFERROR(INDEX('领用录入（明细）'!$B:$L,SMALL($B:$B,ROW(I3)),MATCH(K$7,$D$7:$L$7,0)),"") -> 1 | L10: =IFERROR(INDEX('领用录入（明细）'!$B:$L,SMALL($B:$B,ROW(J3)),MATCH(L$7,$D$7:$L$7,0)),"") -> 0 | M10: =IFERROR(K10*L10,"") -> 0
B11: =IF(AND('领用录入（明细）'!D:D=$F$4,'领用录入（明细）'!C:C>=$J$4,'领用录入（明细）'!C:C<=$L$4),ROW(),"-") -> - | D11: =IFERROR(INDEX('领用录入（明细）'!$B:$L,SMALL($B:$B,ROW(B4)),MATCH(D$7,$D$7:$L$7,0)),"") -> 100 | E11: =IFERROR(INDEX('领用录入（明细）'!$B:$L,SMALL($B:$B,ROW(C4)),MATCH(E$7,$D$7:$L$7,0)),"") -> 44895 | F11: =IFERROR(INDEX('领用录入（明细）'!$B:$L,SMALL($B:$B,ROW(D4)),MATCH(F$7,$D$7:$L$7,0)),"") -> 余慧娟 | G11: =IFERROR(INDEX('领用录入（明细）'!$B:$L,SMALL($B:$B,ROW(E4)),MATCH(G$7,$D$7:$L$7,0)),"") -> 综合办 | H11: =IFERROR(INDEX('领用录入（明细）'!$B:$L,SMALL($B:$B,ROW(F4)),MATCH(H$7,$D$7:$L$7,0)),"") -> 电池双鹿7号 | I11: =IFERROR(INDEX('领用录入（明细）'!$B:$L,SMALL($B:$B,ROW(G4)),MATCH(I$7,$D$7:$L$7,0)),"") -> 节 | J11: =IFERROR(INDEX('领用录入（明细）'!$B:$L,SMALL($B:$B,ROW(H4)),MATCH(J$7,$D$7:$L$7,0)),"") -> 0 | K11: =IFERROR(INDEX('领用录入（明细）'!$B:$L,SMALL($B:$B,ROW(I4)),MATCH(K$7,$D$7:$L$7,0)),"") -> 3 | L11: =IFERROR(INDEX('领用录入（明细）'!$B:$L,SMALL($B:$B,ROW(J4)),MATCH(L$7,$D$7:$L$7,0)),"") -> 0 | M11: =IFERROR(K11*L11,"") -> 0
B12: =IF(AND('领用录入（明细）'!D:D=$F$4,'领用录入（明细）'!C:C>=$J$4,'领用录入（明细）'!C:C<=$L$4),ROW(),"-") -> - | D12: =IFERROR(INDEX('领用录入（明细）'!$B:$L,SMALL($B:$B,ROW(B5)),MATCH(D$7,$D$7:$L$7,0)),"") -> 131 | E12: =IFERROR(INDEX('领用录入（明细）'!$B:$L,SMALL($B:$B,ROW(C5)),MATCH(E$7,$D$7:$L$7,0)),"") -> 44909 | F12: =IFERROR(INDEX('领用录入（明细）'!$B:$L,SMALL($B:$B,ROW(D5)),MATCH(F$7,$D$7:$L$7,0)),"") -> 余慧娟 | G12: =IFERROR(INDEX('领用录入（明细）'!$B:$L,SMALL($B:$B,ROW(E5)),MATCH(G$7,$D$7:$L$7,0)),"") -> 综合办 | H12: =IFERROR(INDEX('领用录入（明细）'!$B:$L,SMALL($B:$B,ROW(F5)),MATCH(H$7,$D$7:$L$7,0)),"") -> 电池南孚5号 | I12: =IFERROR(INDEX('领用录入（明细）'!$B:$L,SMALL($B:$B,ROW(G5)),MATCH(I$7,$D$7:$L$7,0)),"") -> 节 | J12: =IFERROR(INDEX('领用录入（明细）'!$B:$L,SMALL($B:$B,ROW(H5)),MATCH(J$7,$D$7:$L$7,0)),"") -> 0 | K12: =IFERROR(INDEX('领用录入（明细）'!$B:$L,SMALL($B:$B,ROW(I5)),MATCH(K$7,$D$7:$L$7,0)),"") -> 10 | L12: =IFERROR(INDEX('领用录入（明细）'!$B:$L,SMALL($B:$B,ROW(J5)),MATCH(L$7,$D$7:$L$7,0)),"") -> 2.1 | M12: =IFERROR(K12*L12,"") -> 21
B13: =IF(AND('领用录入（明细）'!D:D=$F$4,'领用录入（明细）'!C:C>=$J$4,'领用录入（明细）'!C:C<=$L$4),ROW(),"-") -> - | D13: =IFERROR(INDEX('领用录入（明细）'!$B:$L,SMALL($B:$B,ROW(B7)),MATCH(D$7,$D$7:$L$7,0)),"") -> 148 | E13: =IFERROR(INDEX('领用录入（明细）'!$B:$L,SMALL($B:$B,ROW(C7)),MATCH(E$7,$D$7:$L$7,0)),"") -> 44922 | F13: =IFERROR(INDEX('领用录入（明细）'!$B:$L,SMALL($B:$B,ROW(D7)),MATCH(F$7,$D$7:$L$7,0)),"") -> 余慧娟 | G13: =IFERROR(INDEX('领用录入（明细）'!$B:$L,SMALL($B:$B,ROW(E7)),MATCH(G$7,$D$7:$L$7,0)),"") -> 综合办 | H13: =IFERROR(INDEX('领用录入（明细）'!$B:$L,SMALL($B:$B,ROW(F7)),MATCH(H$7,$D$7:$L$7,0)),"") -> 用款申请单 | I13: =IFERROR(INDEX('领用录入（明细）'!$B:$L,SMALL($B:$B,ROW(G7)),MATCH(I$7,$D$7:$L$7,0)),"") -> 本 | J13: =IFERROR(INDEX('领用录入（明细）'!$B:$L,SMALL($B:$B,ROW(H7)),MATCH(J$7,$D$7:$L$7,0)),"") -> 0 | K13: =IFERROR(INDEX('领用录入（明细）'!$B:$L,SMALL($B:$B,ROW(I7)),MATCH(K$7,$D$7:$L$7,0)),"") -> 1 | L13: =IFERROR(INDEX('领用录入（明细）'!$B:$L,SMALL($B:$B,ROW(J7)),MATCH(L$7,$D$7:$L$7,0)),"") -> 0 | M13: =IFERROR(K13*L13,"") -> 0
B14: =IF(AND('领用录入（明细）'!D:D=$F$4,'领用录入（明细）'!C:C>=$J$4,'领用录入（明细）'!C:C<=$L$4),ROW(),"-") -> - | D14: =IFERROR(INDEX('领用录入（明细）'!$B:$L,SMALL($B:$B,ROW(B8)),MATCH(D$7,$D$7:$L$7,0)),"") -> 149 | E14: =IFERROR(INDEX('领用录入（明细）'!$B:$L,SMALL($B:$B,ROW(C8)),MATCH(E$7,$D$7:$L$7,0)),"") -> 44922 | F14: =IFERROR(INDEX('领用录入（明细）'!$B:$L,SMALL($B:$B,ROW(D8)),MATCH(F$7,$D$7:$L$7,0)),"") -> 余慧娟 | G14: =IFERROR(INDEX('领用录入（明细）'!$B:$L,SMALL($B:$B,ROW(E8)),MATCH(G$7,$D$7:$L$7,0)),"") -> 综合办 | H14: =IFERROR(INDEX('领用录入（明细）'!$B:$L,SMALL($B:$B,ROW(F8)),MATCH(H$7,$D$7:$L$7,0)),"") -> 水笔红色 | I14: =IFERROR(INDEX('领用录入（明细）'!$B:$L,SMALL($B:$B,ROW(G8)),MATCH(I$7,$D$7:$L$7,0)),"") -> 支 | J14: =IFERROR(INDEX('领用录入（明细）'!$B:$L,SMALL($B:$B,ROW(H8)),MATCH(J$7,$D$7:$L$7,0)),"") -> 0 | K14: =IFERROR(INDEX('领用录入（明细）'!$B:$L,SMALL($B:$B,ROW(I8)),MATCH(K$7,$D$7:$L$7,0)),"") -> 2 | L14: =IFERROR(INDEX('领用录入（明细）'!$B:$L,SMALL($B:$B,ROW(J8)),MATCH(L$7,$D$7:$L$7,0)),"") -> 1.3 | M14: =IFERROR(K14*L14,"") -> 2.6
B15: =IF(AND('领用录入（明细）'!D:D=$F$4,'领用录入（明细）'!C:C>=$J$4,'领用录入（明细）'!C:C<=$L$4),ROW(),"-") -> - | D15: =IFERROR(INDEX('领用录入（明细）'!$B:$L,SMALL($B:$B,ROW(B9)),MATCH(D$7,$D$7:$L$7,0)),"") -> 174 | E15: =IFERROR(INDEX('领用录入（明细）'!$B:$L,SMALL($B:$B,ROW(C9)),MATCH(E$7,$D$7:$L$7,0)),"") -> 44930 | F15: =IFERROR(INDEX('领用录入（明细）'!$B:$L,SMALL($B:$B,ROW(D9)),MATCH(F$7,$D$7:$L$7,0)),"") -> 余慧娟 | G15: =IFERROR(INDEX('领用录入（明细）'!$B:$L,SMALL($B:$B,ROW(E9)),MATCH(G$7,$D$7:$L$7,0)),"") -> 综合办 | H15: =IFERROR(INDEX('领用录入（明细）'!$B:$L,SMALL($B:$B,ROW(F9)),MATCH(H$7,$D$7:$L$7,0)),"") -> 有线鼠标 | I15: =IFERROR(INDEX('领用录入（明细）'!$B:$L,SMALL($B:$B,ROW(G9)),MATCH(I$7,$D$7:$L$7,0)),"") -> 个 | J15: =IFERROR(INDEX('领用录入（明细）'!$B:$L,SMALL($B:$B,ROW(H9)),MATCH(J$7,$D$7:$L$7,0)),"") -> 0 | K15: =IFERROR(INDEX('领用录入（明细）'!$B:$L,SMALL($B:$B,ROW(I9)),MATCH(K$7,$D$7:$L$7,0)),"") -> 1 | L15: =IFERROR(INDEX('领用录入（明细）'!$B:$L,SMALL($B:$B,ROW(J9)),MATCH(L$7,$D$7:$L$7,0)),"") -> 30 | M15: =IFERROR(K15*L15,"") -> 30
B16: =IF(AND('领用录入（明细）'!D:D=$F$4,'领用录入（明细）'!C:C>=$J$4,'领用录入（明细）'!C:C<=$L$4),ROW(),"-") -> - | D16: =IFERROR(INDEX('领用录入（明细）'!$B:$L,SMALL($B:$B,ROW(B10)),MATCH(D$7,$D$7:$L$7,0)),"") -> 226 | E16: =IFERROR(INDEX('领用录入（明细）'!$B:$L,SMALL($B:$B,ROW(C10)),MATCH(E$7,$D$7:$L$7,0)),"") -> 44959 | F16: =IFERROR(INDEX('领用录入（明细）'!$B:$L,SMALL($B:$B,ROW(D10)),MATCH(F$7,$D$7:$L$7,0)),"") -> 余慧娟 | G16: =IFERROR(INDEX('领用录入（明细）'!$B:$L,SMALL($B:$B,ROW(E10)),MATCH(G$7,$D$7:$L$7,0)),"") -> 综合办 | H16: =IFERROR(INDEX('领用录入（明细）'!$B:$L,SMALL($B:$B,ROW(F10)),MATCH(H$7,$D$7:$L$7,0)),"") -> 抽纸盒 | I16: =IFERROR(INDEX('领用录入（明细）'!$B:$L,SMALL($B:$B,ROW(G10)),MATCH(I$7,$D$7:$L$7,0)),"") -> 盒 | J16: =IFERROR(INDEX('领用录入（明细）'!$B:$L,SMALL($B:$B,ROW(H10)),MATCH(J$7,$D$7:$L$7,0)),"") -> 0 | K16: =IFERROR(INDEX('领用录入（明细）'!$B:$L,SMALL($B:$B,ROW(I10)),MATCH(K$7,$D$7:$L$7,0)),"") -> 4 | L16: =IFERROR(INDEX('领用录入（明细）'!$B:$L,SMALL($B:$B,ROW(J10)),MATCH(L$7,$D$7:$L$7,0)),"") -> 5.3 | M16: =IFERROR(K16*L16,"") -> 21.2
B17: =IF(AND('领用录入（明细）'!D:D=$F$4,'领用录入（明细）'!C:C>=$J$4,'领用录入（明细）'!C:C<=$L$4),ROW(),"-") -> 17 | D17: =IFERROR(INDEX('领用录入（明细）'!$B:$L,SMALL($B:$B,ROW(B11)),MATCH(D$7,$D$7:$L$7,0)),"") -> 340 | E17: =IFERROR(INDEX('领用录入（明细）'!$B:$L,SMALL($B:$B,ROW(C11)),MATCH(E$7,$D$7:$L$7,0)),"") -> 44977 | F17: =IFERROR(INDEX('领用录入（明细）'!$B:$L,SMALL($B:$B,ROW(D11)),MATCH(F$7,$D$7:$L$7,0)),"") -> 余慧娟 | G17: =IFERROR(INDEX('领用录入（明细）'!$B:$L,SMALL($B:$B,ROW(E11)),MATCH(G$7,$D$7:$L$7,0)),"") -> 综合办 | H17: =IFERROR(INDEX('领用录入（明细）'!$B:$L,SMALL($B:$B,ROW(F11)),MATCH(H$7,$D$7:$L$7,0)),"") -> 挂式纸盒 | I17: =IFERROR(INDEX('领用录入（明细）'!$B:$L,SMALL($B:$B,ROW(G11)),MATCH(I$7,$D$7:$L$7,0)),"") -> 台 | J17: =IFERROR(INDEX('领用录入（明细）'!$B:$L,SMALL($B:$B,ROW(H11)),MATCH(J$7,$D$7:$L$7,0)),"") -> 0 | K17: =IFERROR(INDEX('领用录入（明细）'!$B:$L,SMALL($B:$B,ROW(I11)),MATCH(K$7,$D$7:$L$7,0)),"") -> 1 | L17: =IFERROR(INDEX('领用录入（明细）'!$B:$L,SMALL($B:$B,ROW(J11)),MATCH(L$7,$D$7:$L$7,0)),"") -> 0 | M17: =IFERROR(K17*L17,"") -> 0
B18: =IF(AND('领用录入（明细）'!D:D=$F$4,'领用录入（明细）'!C:C>=$J$4,'领用录入（明细）'!C:C<=$L$4),ROW(),"-") -> 18 | D18: =IFERROR(INDEX('领用录入（明细）'!$B:$L,SMALL($B:$B,ROW(B12)),MATCH(D$7,$D$7:$L$7,0)),"") -> 341 | E18: =IFERROR(INDEX('领用录入（明细）'!$B:$L,SMALL($B:$B,ROW(C12)),MATCH(E$7,$D$7:$L$7,0)),"") -> 44977 | F18: =IFERROR(INDEX('领用录入（明细）'!$B:$L,SMALL($B:$B,ROW(D12)),MATCH(F$7,$D$7:$L$7,0)),"") -> 余慧娟 | G18: =IFERROR(INDEX('领用录入（明细）'!$B:$L,SMALL($B:$B,ROW(E12)),MATCH(G$7,$D$7:$L$7,0)),"") -> 综合办 | H18: =IFERROR(INDEX('领用录入（明细）'!$B:$L,SMALL($B:$B,ROW(F12)),MATCH(H$7,$D$7:$L$7,0)),"") -> 挂式纸盒挂钩 | I18: =IFERROR(INDEX('领用录入（明细）'!$B:$L,SMALL($B:$B,ROW(G12)),MATCH(I$7,$D$7:$L$7,0)),"") -> 根 | J18: =IFERROR(INDEX('领用录入（明细）'!$B:$L,SMALL($B:$B,ROW(H12)),MATCH(J$7,$D$7:$L$7,0)),"") -> 0 | K18: =IFERROR(INDEX('领用录入（明细）'!$B:$L,SMALL($B:$B,ROW(I12)),MATCH(K$7,$D$7:$L$7,0)),"") -> 1 | L18: =IFERROR(INDEX('领用录入（明细）'!$B:$L,SMALL($B:$B,ROW(J12)),MATCH(L$7,$D$7:$L$7,0)),"") -> 0 | M18: =IFERROR(K18*L18,"") -> 0
B19: =IF(AND('领用录入（明细）'!D:D=$F$4,'领用录入（明细）'!C:C>=$J$4,'领用录入（明细）'!C:C<=$L$4),ROW(),"-") -> 19 | D19: =IFERROR(INDEX('领用录入（明细）'!$B:$L,SMALL($B:$B,ROW(B13)),MATCH(D$7,$D$7:$L$7,0)),"") -> 342 | E19: =IFERROR(INDEX('领用录入（明细）'!$B:$L,SMALL($B:$B,ROW(C13)),MATCH(E$7,$D$7:$L$7,0)),"") -> 44977 | F19: =IFERROR(INDEX('领用录入（明细）'!$B:$L,SMALL($B:$B,ROW(D13)),MATCH(F$7,$D$7:$L$7,0)),"") -> 余慧娟 | G19: =IFERROR(INDEX('领用录入（明细）'!$B:$L,SMALL($B:$B,ROW(E13)),MATCH(G$7,$D$7:$L$7,0)),"") -> 综合办 | H19: =IFERROR(INDEX('领用录入（明细）'!$B:$L,SMALL($B:$B,ROW(F13)),MATCH(H$7,$D$7:$L$7,0)),"") -> 纳米海绵 | I19: =IFERROR(INDEX('领用录入（明细）'!$B:$L,SMALL($B:$B,ROW(G13)),MATCH(I$7,$D$7:$L$7,0)),"") -> 个 | J19: =IFERROR(INDEX('领用录入（明细）'!$B:$L,SMALL($B:$B,ROW(H13)),MATCH(J$7,$D$7:$L$7,0)),"") -> 0 | K19: =IFERROR(INDEX('领用录入（明细）'!$B:$L,SMALL($B:$B,ROW(I13)),MATCH(K$7,$D$7:$L$7,0)),"") -> 1 | L19: =IFERROR(INDEX('领用录入（明细）'!$B:$L,SMALL($B:$B,ROW(J13)),MATCH(L$7,$D$7:$L$7,0)),"") -> 0 | M19: =IFERROR(K19*L19,"") -> 0
B20: =IF(AND('领用录入（明细）'!D:D=$F$4,'领用录入（明细）'!C:C>=$J$4,'领用录入（明细）'!C:C<=$L$4),ROW(),"-") -> - | D20: =IFERROR(INDEX('领用录入（明细）'!$B:$L,SMALL($B:$B,ROW(B14)),MATCH(D$7,$D$7:$L$7,0)),"") -> 343 | E20: =IFERROR(INDEX('领用录入（明细）'!$B:$L,SMALL($B:$B,ROW(C14)),MATCH(E$7,$D$7:$L$7,0)),"") -> 44977 | F20: =IFERROR(INDEX('领用录入（明细）'!$B:$L,SMALL($B:$B,ROW(D14)),MATCH(F$7,$D$7:$L$7,0)),"") -> 余慧娟 | G20: =IFERROR(INDEX('领用录入（明细）'!$B:$L,SMALL($B:$B,ROW(E14)),MATCH(G$7,$D$7:$L$7,0)),"") -> 综合办 | H20: =IFERROR(INDEX('领用录入（明细）'!$B:$L,SMALL($B:$B,ROW(F14)),MATCH(H$7,$D$7:$L$7,0)),"") -> 304不锈钢饭勺 | I20: =IFERROR(INDEX('领用录入（明细）'!$B:$L,SMALL($B:$B,ROW(G14)),MATCH(I$7,$D$7:$L$7,0)),"") -> 个 | J20: =IFERROR(INDEX('领用录入（明细）'!$B:$L,SMALL($B:$B,ROW(H14)),MATCH(J$7,$D$7:$L$7,0)),"") -> 0 | K20: =IFERROR(INDEX('领用录入（明细）'!$B:$L,SMALL($B:$B,ROW(I14)),MATCH(K$7,$D$7:$L$7,0)),"") -> 1 | L20: =IFERROR(INDEX('领用录入（明细）'!$B:$L,SMALL($B:$B,ROW(J14)),MATCH(L$7,$D$7:$L$7,0)),"") -> 0 | M20: =IFERROR(K20*L20,"") -> 0
B21: =IF(AND('领用录入（明细）'!D:D=$F$4,'领用录入（明细）'!C:C>=$J$4,'领用录入（明细）'!C:C<=$L$4),ROW(),"-") -> - | D21: =IFERROR(INDEX('领用录入（明细）'!$B:$L,SMALL($B:$B,ROW(B15)),MATCH(D$7,$D$7:$L$7,0)),"") -> 344 | E21: =IFERROR(INDEX('领用录入（明细）'!$B:$L,SMALL($B:$B,ROW(C15)),MATCH(E$7,$D$7:$L$7,0)),"") -> 44977 | F21: =IFERROR(INDEX('领用录入（明细）'!$B:$L,SMALL($B:$B,ROW(D15)),MATCH(F$7,$D$7:$L$7,0)),"") -> 余慧娟 | G21: =IFERROR(INDEX('领用录入（明细）'!$B:$L,SMALL($B:$B,ROW(E15)),MATCH(G$7,$D$7:$L$7,0)),"") -> 综合办 | H21: =IFERROR(INDEX('领用录入（明细）'!$B:$L,SMALL($B:$B,ROW(F15)),MATCH(H$7,$D$7:$L$7,0)),"") -> 抹布 | I21: =IFERROR(INDEX('领用录入（明细）'!$B:$L,SMALL($B:$B,ROW(G15)),MATCH(I$7,$D$7:$L$7,0)),"") -> 瓶 | J21: =IFERROR(INDEX('领用录入（明细）'!$B:$L,SMALL($B:$B,ROW(H15)),MATCH(J$7,$D$7:$L$7,0)),"") -> 0 | K21: =IFERROR(INDEX('领用录入（明细）'!$B:$L,SMALL($B:$B,ROW(I15)),MATCH(K$7,$D$7:$L$7,0)),"") -> 1 | L21: =IFERROR(INDEX('领用录入（明细）'!$B:$L,SMALL($B:$B,ROW(J15)),MATCH(L$7,$D$7:$L$7,0)),"") -> 0 | M21: =IFERROR(K21*L21,"") -> 0
